Workbook
Name SegmentaçãodeDados_ÁREA: #N/A
Name SegmentaçãodeDados_EQUIPE: #N/A

Sheet Mecânica
C59: PESSOAS | D59: Disponível | E59: Pago | F59: %
B60: Gerente de vendas | C60: 2 | D60: 513.33 | F60: =IFERROR(E60/D60,) -> 0
B61: Supervisores Varejo | C61: 11 | D61: 2460.44 | F61: =IFERROR(E61/D61,) -> 0
B62: Supervisores MC/KA | C62: 5 | D62: 2672.83 | F62: =IFERROR(E62/D62,) -> 0
B63: Vendedores varejo | C63: 61 | D63: 12302 | F63: =IFERROR(E63/D63,) -> 0
B64: Vendedores MC/KA | C64: 21 | D64: 13370 | F64: =IFERROR(E64/D64,) -> 0
B65: Gerente Comercial | C65: 1 | D65: 513.33 | F65: =IFERROR(E65/D65,) -> 0
B66: TOTAL | D66: =SUM(D60:D65) -> 31831.93 | E66: =SUM(E60:E65) -> 0 | F66: =IFERROR(E66/D66,) -> 0

Sheet GERAL
J1: 46203.395
B4: VISUALIZAÇÃO | C4: 1 | F4: VISUALIZAÇÃO | G4: All
B5: META R$ | C5: (Vários itens) | F5: META R$ | G5: All
B6: SEGMENTO | C6: VAREJO | F6: SEGMENTO | G6: MÉDIAS CONTAS
B8: EQUIPES | C8: POSITIVAÇÃO 30/60/100 GR | D8: POSITIVAÇÃO + 160 GR | F8: EQUIPE | G8: META | H8: REALIZADO | I8: % | J8: FD 160gr
B9: FLORIPA D | C9: 163 | D9: 7 | F9: FERRERO | G9: 131000 | H9: 154182.18 | I9: 1.1769632 | J9: 55
B10: FLORIPA M | C10: 46 | F10: FLP-SUL MC/KA D | G10: 181800 | H10: 241366.31 | I10: 1.3276475 | J10: 332
B11: LITORAL D | C11: 235 | D11: 15 | F11: FLP-SUL MC/KA M | G11: 5700 | H11: 9115.3 | I11: 1.5991754 | J11: 4
B12: LITORAL M | C12: 35 | D12: 1 | F12: NORTE MC/KA D | G12: 837900 | H12: 1008576.4 | I12: 1.2036954 | J12: 791
B13: NORTE D | C13: 165 | D13: 18 | F13: NORTE MC/KA M | G13: 67800 | H13: 104940.7 | I13: 1.5477979 | J13: 218
B14: SUL D | C14: 102 | D14: 4 | F14: Total Geral | G14: 1224200 | H14: 1518180.9 | I14: 1.2401412 | J14: 1402
B15: SUL M | C15: 33
B16: VALE D | C16: 153 | D16: 6
B17: VALE M | C17: 26
B18: VENDAS INTERNAS | C18: 73 | D18: 7
B19: Total Geral | C19: 1031 | D19: 58
B22: VISUALIZAÇÃO | C22: 1 | F22: VISUALIZAÇÃO | G22: 1
B23: META R$ | C23: (Vários itens) | F23: META R$ | G23: (Vários itens)
B24: SEGMENTO | C24: VAREJO | F24: SEGMENTO | G24: MÉDIAS CONTAS
B26: ÁREA | C26: POSITIVAÇÕ 30 & 60 & 100gr | D26: POSITIVAÇÃO + 160 gr | F26: ÁREA | G26: META | H26: REALIZADO | I26: % | J26: FD 160gr
B27: FLORIPA D | F27: FERRERO
B28: BIGUACU D | C28: 20 | D28: 2 | F28: EXE-FER-1 | G28: 61100 | H28: 77794.2 | I28: 1.2732275
B29: FLORIPA D | C29: 32 | F29: EXE-FER-2 | G29: 69900 | H29: 76387.98 | I29: 1.092818 | J29: 55
B30: FLORIPA-CONT D | C30: 29 | D30: 3 | F30: FLP-SUL MC/KA D
B31: FLORIPA-NORTE D | C31: 28 | F31: KA-CRC PC | G31: 72400 | H31: 96680.12 | I31: 1.3353608
B32: FLORIPA-SUL D | C32: 31 | F32: MC-ARA D | G32: 7300 | H32: 8883.59 | I32: 1.2169301 | J32: 10
B33: PALHOCA-SUL D | C33: 29 | D33: 1 | F33: MC-BGU D | G33: 15000 | H33: 30184.38 | I33: 2.012292 | J33: 26
B34: SAO JOSE D | C34: 44 | D34: 5 | F34: MC-CRC D | G34: 10100 | H34: 12513.44 | I34: 1.2389545 | J34: 29
B35: STO AMARO D | C35: 31 | D35: 1 | F35: MC-FLP D | G35: 6000 | H35: 1794.88 | I35: 0.29914667 | J35: 5
B36: FLORIPA M | F36: MC-IMB D | G36: 6600 | H36: 6951.45 | I36: 1.05325 | J36: 8
B37: FLP-CONV-CONT | C37: 38 | F37: MC-PLH PC | G37: 39800 | H37: 43140.59 | I37: 1.0839344 | J37: 169
B38: FLP-CONV-ILHA | C38: 8 | F38: MC-SJO D | G38: 15100 | H38: 20226.56 | I38: 1.3395073 | J38: 22
B39: LITORAL D | F39: MC-TBCR D | G39: 9500 | H39: 20991.3 | I39: 2.2096105 | J39: 62
B40: BCA D | C40: 95 | D40: 16 | F40: FLP-SUL MC/KA M
B41: BRUSQUE D | C41: 31 | D41: 1 | F41: MC-LAGES | G41: 5700 | H41: 9115.3 | I41: 1.5991754 | J41: 4
B42: CAMBORIU D | C42: 46 | D42: 2 | F42: NORTE MC/KA D
B43: ITAJAI-NORTE D | C43: 31 | D43: 1 | F43: KA-BNU D | G43: 45300 | H43: 91474.91 | I43: 2.0193137
B44: ITAJAI-SUL D | C44: 28 | D44: 2 | F44: KA-BRQ | G44: 723200 | H44: 800941.11 | I44: 1.107496 | J44: 503
B45: ITAPEMA D | C45: 42 | D45: 4 | F45: MC-BNU D | G45: 10500 | H45: 20212.11 | I45: 1.9249629 | J45: 67
B46: LUIZ ALVES D | C46: 41 | F46: MC-ITJ D | G46: 7500 | H46: 14738.46 | I46: 1.965128
...

Sheet CLIENTES
B11: RAZÃO | C11: 30/60/100gr | D11: 30/60/100gr + 160g | E11: R$ TOTAL | F11: FD 160gr
B12: 100012 - PANIFICADORA E CONFEITARIA NM LTDA
B13: 100049 - ACI TIAGO MACHADO
B14: 100109 - POSTO LEAO DO TREVO LTDA
B15: 100111 - SANTA LUZIA COM DE FRUTAS E VERDURA LTDA
B16: 100175 - MAD RESTAURANTES LTDA
B17: 100312 - POSTO MAIOCHI CAMBORIU LTDA | C17: 1 | E17: 37.85
B18: 100355 - AUTO POSTO SM LTDA | C18: 1 | E18: 18.95
B19: 100367 - WALPESCA COMERCIO DE PESCADOS LTDA
B20: 100393 - SUPERMERCADO PALMEIRA LTDA
B21: 100402 - MERCADO SAO MARCOS LTDA
B22: 100429 - ANA PAULA OLIVEIRA DA SILVA
B23: 100542 - SILVIO SOBCZACK
B24: 100583 - G E MINI MERCADO LTDA
B25: 100611 - MERCADO PONTE SERRADA LTDA
B26: 100616 - RESTAURANTE E LANCHONETE SOUZA LTDA
B27: 100624 - ADEMIR BORCHARDT ME
B28: 100695 - ROBERTO SCHULZ E CIA LTDA
B29: 100779 - EMPORIO GIOVANE DEBIAZZI LTDA
B30: 100860 - MERCADO KALINHO LTDA | C30: 1 | E30: 148.32
B31: 100871 - GOLDEN COM DE COMBUSTIVEIS LTDA
B32: 101128 - HOTELARIA ACCOR BRASIL S A
B33: 101173 - ROSSETO E ROSSETO LTDA
B34: 101238 - AUTO POSTO MARINA EIRELI | C34: 1 | E34: 98.53
B35: 101246 - SUPER VIGGANIGO LTDA
B36: 101314 - ROMILDA BURTET VIEIRA ME
B37: 101324 - NELSON PEREIRA DOS SANTOS LANCHONETE
B38: 101348 - BRYCH COMERCIO DE GENEROS ALIMENTICIOS LTDA
B39: 101351 - SUPERMERCADO CHAVES KULPA LTDA | C39: 1 | E39: 62.22
B40: 101353 - DANIEL AUGUSTO FERNANDES PEREIRA
B41: 101385 - POSTO COCAL DO SUL LTDA
B42: 101401 - LIJIANARA MENDES EIRELI
B43: 101440 - PAES E PAES LTDA | C43: 1 | E43: 324.86
B44: 101707 - COMERCIAL DE FERRAGENS COMIN LTDA
B45: 101766 - OLIVEIRA E MADRUGA LTDA
B46: 101791 - PANIF E CONF PADRE ROMA LTDA
B47: 101852 - AUTO POSTO BELA JOIA LTDA
B48: 101871 - EKO SUPERMERCADO LTDA | C48: 1 | E48: 149.68
B49: 101912 - KARINA MACARINI DAROLT E CIA LTDA
B50: 101928 - A ANGELONI E CIA LTDA
...

Sheet ITENS
B2: GRUPO | C2: Código Produto | D2: Produto
B3: 30gr & 60gr & 100gr | C3: 43766 | D3: PIPOCA KI PIPOKA 100 GR DOCE
B4: 30gr & 60gr & 100gr | C4: 43767 | D4: PIPOCA KI PIPOKA 100 GR SALGADA
B5: 30gr & 60gr & 100gr | C5: 60890 | D5: PIPOCA KI PIPOKA 30 GR DOCE
B6: 30gr & 60gr & 100gr | C6: 60892 | D6: PIPOCA KI PIPOKA 30 GR SALGADA
B7: 30gr & 60gr & 100gr | C7: 43764 | D7: PIPOCA KI PIPOKA 60 GR DOCE
B8: 30gr & 60gr & 100gr | C8: 43765 | D8: PIPOCA KI PIPOKA 60 GR SALGADA
B9: 160 gr | C9: 119670 | D9: KI PIPOKA 160 - FD20

Sheet METAS MENSAIS
B1: 46143 | G1: =SUBTOTAL(9,Tabela2[M$]) -> 1550000 | H1: =SUBTOTAL(9,Tabela2[MP]) -> 2140 | R1: =SUM(Q2:Q147) -> 0
B2: CÓD | C2: ÁREA | D2: EQUIPE | E2: FORNECEDOR | F2: NOME | G2: M$ | H2: MP | I2: VISUALIZAÇÃO | J2: MÊS | K2: Coluna1
B3: 1 | C3: MULLER(SC) | D3: 50 | E3: 177264 | F3: KIPIPOKA | G3: 0 | H3: 0 | I3: =IF(SUM(Tabela2[[#This Row],[M$]:[MP]])=0,0,1) -> 0 | J3: 5 | K3: =_xlfn.XLOOKUP(Tabela2[[#This Row],[CÓD]],X!D:D,X!F:F,"-",0,1) -> -
B4: 78 | C4: KA-SBS | D4: 25 | E4: 177264 | F4: KIPIPOKA | G4: 0 | H4: 0 | I4: =IF(SUM(Tabela2[[#This Row],[M$]:[MP]])=0,0,1) -> 0 | J4: 5 | K4: =_xlfn.XLOOKUP(Tabela2[[#This Row],[CÓD]],X!D:D,X!F:F,"-",0,1) -> 0
B5: 179 | C5: KA-BRQ | D5: 25 | E5: 177264 | F5: KIPIPOKA | G5: 723200 | H5: 25 | I5: =IF(SUM(Tabela2[[#This Row],[M$]:[MP]])=0,0,1) -> 1 | J5: 5 | K5: =_xlfn.XLOOKUP(Tabela2[[#This Row],[CÓD]],X!D:D,X!F:F,"-",0,1) -> 723200
B6: 201 | C6: BCA D | D6: 35 | E6: 177264 | F6: KIPIPOKA | G6: 18000 | H6: 57 | I6: =IF(SUM(Tabela2[[#This Row],[M$]:[MP]])=0,0,1) -> 1 | J6: 5 | K6: =_xlfn.XLOOKUP(Tabela2[[#This Row],[CÓD]],X!D:D,X!F:F,"-",0,1) -> 18000
B7: 224 | C7: KA-CRC PC | D7: 32 | E7: 177264 | F7: KIPIPOKA | G7: 72400 | H7: 18 | I7: =IF(SUM(Tabela2[[#This Row],[M$]:[MP]])=0,0,1) -> 1 | J7: 5 | K7: =_xlfn.XLOOKUP(Tabela2[[#This Row],[CÓD]],X!D:D,X!F:F,"-",0,1) -> 72400
B8: 307 | C8: MC-ARA M | D8: 23 | E8: 177264 | F8: KIPIPOKA | G8: 0 | H8: 0 | I8: =IF(SUM(Tabela2[[#This Row],[M$]:[MP]])=0,0,1) -> 0 | J8: 5 | K8: =_xlfn.XLOOKUP(Tabela2[[#This Row],[CÓD]],X!D:D,X!F:F,"-",0,1) -> 0
B9: 359 | C9: MC-ITPE D | D9: 25 | E9: 177264 | F9: KIPIPOKA | G9: 20400 | H9: 5 | I9: =IF(SUM(Tabela2[[#This Row],[M$]:[MP]])=0,0,1) -> 1 | J9: 5 | K9: =_xlfn.XLOOKUP(Tabela2[[#This Row],[CÓD]],X!D:D,X!F:F,"-",0,1) -> 20400
B10: 383 | C10: MC-TBCR M | D10: 23 | E10: 177264 | F10: KIPIPOKA | G10: 0 | H10: 0 | I10: =IF(SUM(Tabela2[[#This Row],[M$]:[MP]])=0,0,1) -> 0 | J10: 5 | K10: =_xlfn.XLOOKUP(Tabela2[[#This Row],[CÓD]],X!D:D,X!F:F,"-",0,1) -> 0
B11: 417 | C11: KA-ROS | D11: 26 | E11: 177264 | F11: KIPIPOKA | G11: 67800 | H11: 7 | I11: =IF(SUM(Tabela2[[#This Row],[M$]:[MP]])=0,0,1) -> 1 | J11: 5 | K11: =_xlfn.XLOOKUP(Tabela2[[#This Row],[CÓD]],X!D:D,X!F:F,"-",0,1) -> 67800
B12: 501 | C12: SAO BENTO D | D12: 38 | E12: 177264 | F12: KIPIPOKA | G12: 12800 | H12: 44 | I12: =IF(SUM(Tabela2[[#This Row],[M$]:[MP]])=0,0,1) -> 1 | J12: 5 | K12: =_xlfn.XLOOKUP(Tabela2[[#This Row],[CÓD]],X!D:D,X!F:F,"-",0,1) -> 12800
B13: 683 | C13: MC-ITPE M | D13: 26 | E13: 177264 | F13: KIPIPOKA | G13: 0 | H13: 0 | I13: =IF(SUM(Tabela2[[#This Row],[M$]:[MP]])=0,0,1) -> 0 | J13: 5 | K13: =_xlfn.XLOOKUP(Tabela2[[#This Row],[CÓD]],X!D:D,X!F:F,"-",0,1) -> 0
B14: 771 | C14: MC-FLP D | D14: 32 | E14: 177264 | F14: KIPIPOKA | G14: 6000 | H14: 4 | I14: =IF(SUM(Tabela2[[#This Row],[M$]:[MP]])=0,0,1) -> 1 | J14: 5 | K14: =_xlfn.XLOOKUP(Tabela2[[#This Row],[CÓD]],X!D:D,X!F:F,"-",0,1) -> 6000
... B149: 5009 | C149: KA-BNU M | D149: 26 | E149: 177264 | F149: KIPIPOKA | G149: 0 | H149: 0 | I149: =IF(SUM(Tabela2[[#This Row],[M$]:[MP]])=0,0,1) -> 0 | J149: 5 | K149: =_xlfn.XLOOKUP(Tabela2[[#This Row],[CÓD]],X!D:D,X!F:F,"-",0,1) -> 0

Sheet X
F1: =SUM(Tabela3[META R$]) -> 1550000
B2: SEGMENTO | C2: EQUIPE | D2: CÓD | E2: ÁREA | F2: META R$ | G2: VISUALIZAÇÃO | H2: PAUTA | K2: Rótulos de Linha | L2: META TT - POSITIVAÇÃO | M2: POSITIVAÇÃO TOTAL | N2: % P
B3: DMULLER | C3: GERENTE PAUTA M | D3: 3949 | E3: GERENTE PAUTA M | F3: =SUMIF('METAS MENSAIS'!$B:$B,X!$D3,'METAS MENSAIS'!$G:$G) -> 0 | G3: 0 | H3: DMULLER | K3: DMULLER | L3: 3000 | M3: 2984 | N3: 0.99466667
B4: DMULLER | C4: GERENTE PAUTA D | D4: 4099 | E4: GERENTE PAUTA D | F4: =SUMIF('METAS MENSAIS'!$B:$B,X!$D4,'METAS MENSAIS'!$G:$G) -> 0 | G4: 0 | H4: DMULLER
B5: MÉDIAS CONTAS | C5: FERRERO | D5: 4003 | E5: FERRERO | F5: =SUMIF('METAS MENSAIS'!$B:$B,X!$D5,'METAS MENSAIS'!$G:$G) -> 0 | G5: 1 | H5: DMULLER | K5: Rótulos de Linha | L5: META TT - R$ | M5: R$ | N5: % R$
B6: DMULLER | C6: BAUDUCCO-VISCONTI | D6: 3506 | E6: PANDURATA | F6: =SUMIF('METAS MENSAIS'!$B:$B,X!$D6,'METAS MENSAIS'!$G:$G) -> 0 | G6: 0 | H6: DMULLER | K6: DMULLER | L6: 1600000 | M6: 1921081 | N6: 1.2006756
B7: DMULLER | C7: JOHNSON | D7: 3947 | E7: JOHNSON | F7: =SUMIF('METAS MENSAIS'!$B:$B,X!$D7,'METAS MENSAIS'!$G:$G) -> 0 | G7: 0 | H7: DMULLER
B8: DMULLER | C8: MERCHANDISING | D8: 4076 | E8: MERCHAN JOHNSON | F8: =SUMIF('METAS MENSAIS'!$B:$B,X!$D8,'METAS MENSAIS'!$G:$G) -> 0 | G8: 0 | H8: DMULLER
B9: DMULLER | C9: MERCHANDISING | D9: 3964 | E9: MERCHAN SUL | F9: =SUMIF('METAS MENSAIS'!$B:$B,X!$D9,'METAS MENSAIS'!$G:$G) -> 0 | G9: 0 | H9: DMULLER
B10: DMULLER | C10: MERCHANDISING | D10: 5011 | E10: MERCHAN NORTE | F10: =SUMIF('METAS MENSAIS'!$B:$B,X!$D10,'METAS MENSAIS'!$G:$G) -> 0 | G10: 0 | H10: DMULLER | L10: GAP | M10: REAL
B11: DMULLER | C11: MERCHANDISING | D11: 3959 | E11: MERCHAN FERRERO | F11: =SUMIF('METAS MENSAIS'!$B:$B,X!$D11,'METAS MENSAIS'!$G:$G) -> 0 | G11: 0 | H11: DMULLER | L11: =IF($L$6-$M$6<0,0,$L$6-$M$6) -> 0 | M11: =$M$6 -> 1921081
B12: DMULLER | C12: EXC MARCAS - 48 | D12: 3231 | E12: MARCAS | F12: =SUMIF('METAS MENSAIS'!$B:$B,X!$D12,'METAS MENSAIS'!$G:$G) -> 12600 | G12: 0 | H12: DMULLER
B13: VAREJO | C13: VENDAS INTERNAS | D13: 3961 | E13: LIDER | F13: =SUMIF('METAS MENSAIS'!$B:$B,X!$D13,'METAS MENSAIS'!$G:$G) -> 0 | G13: 1 | H13: M | L13: GAP | M13: REAL
B14: VAREJO | C14: VENDAS INTERNAS | D14: 3272 | E14: VENDAS-2 | F14: =SUMIF('METAS MENSAIS'!$B:$B,X!$D14,'METAS MENSAIS'!$G:$G) -> 1500 | G14: 1 | H14: M | L14: =IF($L$3-$M$36<0,0,$L$3-$M$3) -> 16 | M14: =M3 -> 2984
B15: VAREJO | C15: VENDAS INTERNAS | D15: 3653 | E15: VENDAS-6 | F15: =SUMIF('METAS MENSAIS'!$B:$B,X!$D15,'METAS MENSAIS'!$G:$G) -> 1900 | G15: 1 | H15: M
B16: VAREJO | C16: VENDAS INTERNAS | D16: 3670 | E16: VENDAS-8 | F16: =SUMIF('METAS MENSAIS'!$B:$B,X!$D16,'METAS MENSAIS'!$G:$G) -> 2100 | G16: 1 | H16: M
B17: MÉDIAS CONTAS | C17: FERRERO | D17: 3717 | E17: SUP-FER/MP | F17: =SUMIF('METAS MENSAIS'!$B:$B,X!$D17,'METAS MENSAIS'!$G:$G) -> 0 | G17: 1 | H17: D
B18: MÉDIAS CONTAS | C18: FERRERO | D18: 3946 | E18: EXE-FER-1 | F18: =SUMIF('METAS MENSAIS'!$B:$B,X!$D18,'METAS MENSAIS'!$G:$G) -> 61100 | G18: 1 | H18: D
B19: MÉDIAS CONTAS | C19: FERRERO | D19: 3962 | E19: EXE-FER-2 | F19: =SUMIF('METAS MENSAIS'!$B:$B,X!$D19,'METAS MENSAIS'!$G:$G) -> 69900 | G19: 1 | H19: D
B20: MÉDIAS CONTAS | C20: FERRERO | D20: 3984 | E20: EXE-FER-4 | F20: =SUMIF('METAS MENSAIS'!$B:$B,X!$D20,'METAS MENSAIS'!$G:$G) -> 0 | G20: 1 | H20: D
B21: MÉDIAS CONTAS | C21: FERRERO | D21: 3983 | E21: EXE-FER-3 | F21: =SUMIF('METAS MENSAIS'!$B:$B,X!$D21,'METAS MENSAIS'!$G:$G) -> 0 | G21: 1 | H21: D
B22: MÉDIAS CONTAS | C22: FLP-SUL MC/KA D | D22: 540 | E22: SUP-FKA PC | F22: =SUMIF('METAS MENSAIS'!$B:$B,X!$D22,'METAS MENSAIS'!$G:$G) -> 0 | G22: 1 | H22: D
B23: MÉDIAS CONTAS | C23: FLP-SUL MC/KA D | D23: 224 | E23: KA-CRC PC | F23: =SUMIF('METAS MENSAIS'!$B:$B,X!$D23,'METAS MENSAIS'!$G:$G) -> 72400 | G23: 1 | H23: D
B24: MÉDIAS CONTAS | C24: FLP-SUL MC/KA D | D24: 3919 | E24: MC-TBCR D | F24: =SUMIF('METAS MENSAIS'!$B:$B,X!$D24,'METAS MENSAIS'!$G:$G) -> 9500 | G24: 1 | H24: D
B25: MÉDIAS CONTAS | C25: FLP-SUL MC/KA D | D25: 4054 | E25: MC-ARA D | F25: =SUMIF('METAS MENSAIS'!$B:$B,X!$D25,'METAS MENSAIS'!$G:$G) -> 7300 | G25: 1 | H25: D
B26: MÉDIAS CONTAS | C26: FLP-SUL MC/KA D | D26: 3956 | E26: MC-IMB D | F26: =SUMIF('METAS MENSAIS'!$B:$B,X!$D26,'METAS MENSAIS'!$G:$G) -> 6600 | G26: 1 | H26: D
... B179: VAREJO | C179: VALE M | D179: 4064 | E179: OPR-VALE M | F179: =SUMIF('METAS MENSAIS'!$B:$B,X!$D179,'METAS MENSAIS'!$G:$G) -> 0 | G179: 1 | H179: M
B180: DMULLER | C180: 0 | D180: 899 | E180: E-COMERCE | F180: =SUMIF('METAS MENSAIS'!$B:$B,X!$D180,'METAS MENSAIS'!$G:$G) -> 0 | G180: 0 | H180: DMULLER
