Workbook
Name SegmentaçãodeDados_ÁREA: #N/A
Name SegmentaçãodeDados_EQUIPE: #N/A
Name SegmentaçãodeDados_MÊS: #N/A

Sheet Mecânica
C33: Disponivel | D33: Pago | E33: %
B34: GERENTE D | C34: 0 | D34: 0 | E34: =IFERROR(D34/C34,) -> 0
B35: GERENTE M | C35: 1400 | D35: 0 | E35: =IFERROR(D35/C35,) -> 0
B36: SUPERVISORES/CONSULTORES | C36: 6500 | D36: 0 | E36: =IFERROR(D36/C36,) -> 0
B37: VENDEDORES/EXECUTIVO | C37: 2500 | D37: 0 | E37: =IFERROR(D37/C37,) -> 0
B38: MERCHANDISING EXTERNO | C38: 0 | D38: 0 | E38: =IFERROR(D38/C39,) -> 0
B39: MERCHANDISING INTERNO | C39: 0 | D39: 0 | E39: =IFERROR(D39/#REF!,) -> 0
B40: TOTAL | C40: =SUM(C33:C39) -> 10400 | D40: =SUM(D33:D39) -> 0 | E40: =IFERROR(D40/C40,) -> 0
C135: Disponível | D135: Pessoas | E135: Disponível TT | F135: Pago | G135: %
B136: GERENTE DE VENDAS | C136: 1500 | D136: 2 | E136: =C136*D136 -> 3000 | F136: 0 | G136: =IFERROR(F136/E136,) -> 0
B137: VENDEDORES VAREJO | C137: 800 | D137: 10 | E137: =C137*D137 -> 8000 | F137: 0 | G137: =IFERROR(F137/E137,) -> 0
B138: VENDEDORES MC/KA | C138: 956 | D138: 9 | E138: =C138*D138 -> 8604 | F138: 0 | G138: =IFERROR(F138/E138,) -> 0
B139: SUPERVISOR VAREJO | C139: 900 | D139: 10 | E139: =C139*D139 -> 9000 | F139: 0 | G139: =IFERROR(F139/E139,) -> 0
B140: SUPERVISOR MC/KA | C140: 550 | D140: 4 | E140: =C140*D140 -> 2200 | F140: 0 | G140: =IFERROR(F140/E140,) -> 0
B141: PROMOTORES | C141: 250 | D141: 30 | E141: =C141*D141 -> 7500 | F141: 0 | G141: =IFERROR(F141/E141,) -> 0
B142: EXTRA | C142: 1300 | D142: 2 | E142: =C142*D142 -> 2600 | F142: 0 | G142: =IFERROR(F142/E142,) -> 0
B143: TOTAL | C143: =SUM(C136:C141) -> 4956 | E143: =SUM(E136:E141) -> 38304 | F143: =SUM(F136:F141) -> 0 | G143: =IFERROR(F143/E143,) -> 0

Sheet ITENS
B4: GRUPO | C4: CÓD | D4: DESCRIÇÃO
B5: LANÇAMENTOS | C5: 125667 | D5: SH PASTA DE AMENDOIM 500 GR POWER CARAMEL SALGADO
B6: LANÇAMENTOS | C6: 125666 | D6: SH PASTA DE AMENDOIM 500 GR POWER ORIGINAL
B7: LANÇAMENTOS | C7: 125572 | D7: SH PASTA AMEN INTEGRAL 500 GR CREAMY
B8: LANÇAMENTOS | C8: 125573 | D8: SH PASTA AMEN INTEGRAL 500 GR CRUNCHY
B9: LANÇAMENTOS | C9: 124628 | D9: PACOQUITA COCO QUEIMADO
B10: LANÇAMENTOS | C10: 125795 | D10: PACOQUITA MAÇA DO AMOR
B11: LANÇAMENTOS | C11: 125794 | D11: PACOQUITA ACUCAR MASCAVO 750
B12: LANÇAMENTOS | C12: 125798 | D12: PACOQUITA ACUCAR MASCAVO 220
B13: LANÇAMENTOS | C13: 125805 | D13: S HELENA MENDORATO 90 GR BACON CA
B14: LANÇAMENTOS | C14: 125807 | D14: S HELENA MENDORATO 90 GR BUFFALO EUA
B15: LANÇAMENTOS | C15: 125804 | D15: S HELENA MENDORATO 90 GR PICANHA BR
B16: LANÇAMENTOS | C16: 125806 | D16: S HELENA MENDORATO 90 GR TACO MX
... B25: PAÇOQUITA ZERO | C25: 88072 | D25: S HELENA PACOQUITA ROLHA 102 G DIET EMB C/6*

Sheet GERAL
E4: ST | F4: (Vários itens)
E6: MÊS | F6: Valores
D7: POSITIVAÇÃO DMULLER | E7: ABRIL | H7: MAIO | K7: JUNHO | N7: JULHO
E8: META | F8: REALIZADO | G8: % P | H8: META | I8: REALIZADO | J8: % P | K8: META | L8: REALIZADO | M8: % P | N8: META | O8: REALIZADO | P8: % P
E9: 3954 | F9: 4269 | G9: 1.0796662 | H9: 4565 | I9: 4604 | J9: 1.0085433 | K9: 4587 | L9: 3041 | M9: 0.66296054 | N9: 4800
E12: MÊS | F12: Valores
D13: FATURAMENTO DMULLER | E13: ABRIL | H13: MAIO | K13: JUNHO | N13: JULHO | Q13: Total META | R13: Total R$ | S13: Total % R$
E14: META | F14: R$ | G14: % R$ | H14: META | I14: R$ | J14: % R$ | K14: META | L14: R$ | M14: % R$ | N14: META | O14: R$ | P14: % R$
E15: 1300000 | F15: 1342212.8 | G15: 1.0324714 | H15: 3600000 | I15: 3046803 | J15: 0.84633418 | K15: 1700000 | L15: 1435479.1 | M15: 0.84439949 | N15: 1600000 | Q15: 8200000 | R15: 5824495 | S15: 0.71030427
D18: 46113 | S18: {=DT_ATT19[Ultima Atualização]} -> 46192.449
D19: =AUX!T103/AUX!S103 -> 0.6557377
D20: PROGRESSO DA CAMPANHA

Sheet AUX
B101: =GERAL!E9 -> 3954 | E101: =GERAL!H9 -> 4565 | H101: =GERAL!K9 -> 4587 | K101: =GERAL!N9 -> 4800 | Q101: Ultima Atualização | T101: =TODAY() -> 46192
B102: REALIZADO | C102: GAP | E102: REALIZADO | F102: GAP | H102: REALIZADO | I102: GAP | K102: REALIZADO | L102: GAP | Q102: 46192.449 | S102: 46113 | T102: 46234
B103: =GERAL!F9 -> 4269 | C103: =IF(B101-Tabela2[[#This Row],[REALIZADO]]<=0,0,B101-Tabela2[[#This Row],[REALIZADO]]) -> 0 | E103: =GERAL!I9 -> 4604 | F103: =IF(E101-Tabela2[[#This Row],[REALIZADO]]<=0,0,E101-Tabela2[[#This Row],[REALIZADO]]) -> 296 | H103: =GERAL!L9 -> 3041 | I103: =IF(H101-Tabela2[[#This Row],[REALIZADO]]<=0,0,H101-Tabela2[[#This Row],[REALIZADO]]) -> 318 | K103: =GERAL!O9 -> 0 | L103: =IF(K101-Tabela2[[#This Row],[REALIZADO]]<=0,0,K101-Tabela2[[#This Row],[REALIZADO]]) -> 531 | S103: =_xlfn.DAYS($T$102,$S$102)+1 -> 122 | T103: =_xlfn.DAYS($T$101,$S$102)+1 -> 80
Q104: ATUALIZAÇÃO
B105: =GERAL!E15 -> 1300000 | E105: =GERAL!H15 -> 3600000 | H105: =GERAL!K15 -> 1700000 | K105: =GERAL!N15 -> 1600000 | N105: =GERAL!Q15 -> 8200000 | Q105: {=DT_ATT[Ultima Atualização]} -> 46192.449
B106: REALIZADO | C106: GAP | E106: REALIZADO | F106: GAP | H106: REALIZADO | I106: GAP | K106: REALIZADO | L106: GAP | N106: REALIZADO | O106: GAP
B107: =GERAL!F15 -> 1342212.8 | C107: =IF(B105-Tabela211[[#This Row],[REALIZADO]]<=0,0,B105-Tabela211[[#This Row],[REALIZADO]]) -> 0 | E107: =GERAL!I15 -> 3046803 | F107: =IF(E105-Tabela512[[#This Row],[REALIZADO]]<=0,0,E105-Tabela512[[#This Row],[REALIZADO]]) -> 553196.95 | H107: =GERAL!L15 -> 1435479.1 | I107: =IF(H105-Tabela815[[#This Row],[REALIZADO]]<=0,0,H105-Tabela815[[#This Row],[REALIZADO]]) -> 264520.87 | K107: =GERAL!O15 -> 0 | L107: =IF(K105-Tabela916[[#This Row],[REALIZADO]]<=0,0,K105-Tabela916[[#This Row],[REALIZADO]]) -> 1600000 | N107: =GERAL!R15 -> 5824495 | O107: =IF(N105-Tabela91617[[#This Row],[REALIZADO]]<=0,0,N105-Tabela91617[[#This Row],[REALIZADO]]) -> 2375505
Q108: Ultima Atualização
Q109: 46192.449

Sheet VAREJO
D3: ST | E3: (Vários itens)
E5: MÊS | F5: Valores | T5: MÊS | U5: Valores
E6: ABRIL | H6: MAIO | K6: JUNHO | N6: JULHO | T6: TOTAL
D7: EQUIPE | E7: META | F7: POSITIVAÇÃO | G7: % P | H7: META | I7: POSITIVAÇÃO | J7: % P | K7: META | L7: POSITIVAÇÃO | M7: % P | N7: META | O7: POSITIVAÇÃO | P7: % P | S7: EQUIPE | T7: META R$ | U7: R$ | V7: % R
D8: FLORIPA M | E8: 654 | F8: 551 | G8: 0.84250765 | H8: 755 | I8: 610 | J8: 0.80794702 | K8: 760 | L8: 414 | M8: 0.54473684 | N8: 0 | S8: FLORIPA M | T8: 261000.08 | U8: 160393.3 | V8: 0.61453353
D9: LITORAL M | E9: 902 | F9: 954 | G9: 1.0576497 | H9: 1040 | I9: 970 | J9: 0.93269231 | K9: 1044 | L9: 671 | M9: 0.64272031 | N9: 0 | S9: LITORAL M | T9: 716500.78 | U9: 530571.11 | V9: 0.74050319
D10: NORTE D | E10: 42 | F10: 20 | G10: 0.47619048 | H10: 48 | I10: 36 | J10: 0.75 | K10: 48 | L10: 28 | M10: 0.58333333 | N10: 0 | S10: NORTE D | T10: 8499.24 | U10: 10556.93 | V10: 1.2421028
D11: NORTE M | E11: 684 | F11: 755 | G11: 1.1038012 | H11: 791 | I11: 831 | J11: 1.0505689 | K11: 792 | L11: 444 | M11: 0.56060606 | N11: 0 | S11: NORTE M | T11: 360500.59 | U11: 328398.95 | V11: 0.9109526
D12: SUL D | E12: 152 | F12: 112 | G12: 0.73684211 | H12: 175 | I12: 115 | J12: 0.65714286 | K12: 177 | L12: 96 | M12: 0.54237288 | N12: 0 | S12: SUL D | T12: 58499.73 | U12: 34730.12 | V12: 0.59368001
D13: SUL M | E13: 768 | F13: 827 | G13: 1.0768229 | H13: 887 | I13: 919 | J13: 1.0360767 | K13: 891 | L13: 509 | M13: 0.57126824 | N13: 0 | S13: SUL M | T13: 234499.41 | U13: 185550.79 | V13: 0.79126336
D14: VALE M | E14: 685 | F14: 634 | G14: 0.92554745 | H14: 792 | I14: 668 | J14: 0.84343434 | K14: 796 | L14: 511 | M14: 0.6419598 | N14: 0 | S14: VALE M | T14: 306997.71 | U14: 274039.8 | V14: 0.89264444
D15: VENDAS INTERNAS | E15: 67 | F15: 142 | G15: 2.119403 | H15: 77 | I15: 156 | J15: 2.025974 | K15: 79 | L15: 136 | M15: 1.721519 | N15: 0 | S15: VENDAS INTERNAS | T15: 86499.88 | U15: 50793.56 | V15: 0.5872096
B16: =COUNTIF(Tabela358[VALIDAÇÃO VENDEDOR],">1") -> 0
B17: =COUNTIF(Tabela35[VALIDAÇÃO VENDEDOR],">1") -> 0
B18: VAREJO M | AJ18: PONTUAÇÕES DO RANKING
B19: GRUPO | C19: VAREJO M
B20: ST | C20: (Vários itens) | R20: GRUPO | S20: VAREJO M | X20: GRUPO | Y20: VAREJO M | AC20: GRUPO | AD20: VAREJO M
X21: ST | Y21: (Vários itens) | AC21: ST | AD21: (Vários itens)
E22: MÊS | F22: Valores | T22: MÊS | U22: Valores
E23: ABRIL | H23: MAIO | K23: JUNHO | N23: JULHO | T23: TOTAL | X23: CONTAGEM ITENS | AC23: POSITIVAÇÃO PAÇOQUITA | AG23: MERCHANDISING | AJ23: PONTUAÇÕES POSITIVAÇÃO | AO23: FATURAMENTO | AQ23: ITENS ESPECIAIS | AT23: MERCHANDISING | AW23: RANKING
B24: EQUIPE | C24: ID | D24: ÁREA | E24: META | F24: POSITIVAÇÃO | G24: % P | H24: META | I24: POSITIVAÇÃO | J24: % P | K24: META | L24: POSITIVAÇÃO | M24: % P | N24: META | O24: POSITIVAÇÃO | P24: % P | R24: EQUIPE | S24: ID | T24: META R$ | U24: R$ | V24: % $ | Z24: LANÇAMENTOS | AA24: PAÇOQUITA ZERO | AE24: PAÇOQUITA ZERO | AG24: BARRACA MONTADA | AH24: PONTO EXTRA | AJ24: POSI ABRIL | AK24: POSI MAIO | AL24: POSI JUNHO | AM24: POSI JULHO | AN24: Coluna1 | AO24: R$ TOTAL | AP24: Coluna12 | AQ24: LANÇAMENTOS | AR24: PAÇOCA ZERO | AS24: Coluna122 | AT24: BARRACAS | AU24: PONTO EXTRA | AV24: Coluna1222 | AW24: TOTAL | AX24: RANKING | AY24: VALIDAÇÃO VENDEDOR
B25: FLORIPA M | C25: 4026 | D25: FLP-CONV-ILHA | E25: 77 | F25: 30 | G25: 0.38961039 | H25: 90 | I25: 49 | J25: 0.54444444 | K25: 90 | L25: 13 | M25: 0.14444444 | N25: 0 | R25: FLORIPA M | S25: 4026 | T25: 29499.61 | U25: 8586.78 | V25: 0.29108114 | X25: FLORIPA M | Y25: 4026 | Z25: 3 | AA25: 39 | AC25: FLORIPA M | AD25: 4026 | AE25: 31 | AG25: =SUMIF(CLIENTES!$C:$C,VAREJO!$C25,CLIENTES!$L:$L) -> 0 | AH25: =SUMIF(CLIENTES!$C:$C,VAREJO!$C25,CLIENTES!$M:$M) -> 0 | AJ25: =IF(G25>=100%,2,0) -> 0 | AK25: =IF(J25>=100%,2,0) -> 0 | AL25: =IF(M25>=100%,2,0) -> 0 | AM25: =IF(P25>=100%,2,0) -> 0 | AO25: =IF($V25>=100%,10,0) -> 0 | AQ25: =AA25 -> 39 | AR25: =$AE25 -> 31 | AT25: =Tabela3[[#This Row],[BARRACA MONTADA]]*5 -> 0 | AU25: =Tabela3[[#This Row],[PONTO EXTRA]]*5 -> 0 | AW25: =SUM(Tabela35[[#This Row],[POSI ABRIL]:[PONTO EXTRA]]) -> 70 | AX25: =_xlfn.RANK.EQ(Tabela35[[#This Row],[TOTAL]],Tabela35[TOTAL],0)& "º" -> 31º | AY25: =COUNTA(_xlfn.UNIQUE(_xlfn.VSTACK(AD25,Y25,S25,C25))) -> 1
C26: 4027 | D26: FLORIPA M | E26: 61 | F26: 67 | G26: 1.0983607 | H26: 71 | I26: 70 | J26: 0.98591549 | K26: 71 | L26: 47 | M26: 0.66197183 | N26: 0 | S26: 4027 | T26: 27000.18 | U26: 17661.98 | V26: 0.65414305 | Y26: 4027 | Z26: 11 | AA26: 45 | AD26: 4027 | AE26: 38 | AG26: =SUMIF(CLIENTES!$C:$C,VAREJO!$C26,CLIENTES!$L:$L) -> 0 | AH26: =SUMIF(CLIENTES!$C:$C,VAREJO!$C26,CLIENTES!$M:$M) -> 0 | AJ26: =IF(G26>=100%,2,0) -> 2 | AK26: =IF(J26>=100%,2,0) -> 0 | AL26: =IF(M26>=100%,2,0) -> 0 | AM26: =IF(P26>=100%,2,0) -> 0 | AO26: =IF($V26>=100%,10,0) -> 0 | AQ26: =AA26 -> 45 | AR26: =$AE26 -> 38 | AT26: =Tabela3[[#This Row],[BARRACA MONTADA]]*5 -> 0 | AU26: =Tabela3[[#This Row],[PONTO EXTRA]]*5 -> 0 | AW26: =SUM(Tabela35[[#This Row],[POSI ABRIL]:[PONTO EXTRA]]) -> 85 | AX26: =_xlfn.RANK.EQ(Tabela35[[#This Row],[TOTAL]],Tabela35[TOTAL],0)& "º" -> 19º | AY26: =COUNTA(_xlfn.UNIQUE(_xlfn.VSTACK(AD26,Y26,S26,C26))) -> 1
C27: 4028 | D27: PALHOCA-SUL M | E27: 73 | F27: 59 | G27: 0.80821918 | H27: 84 | I27: 53 | J27: 0.63095238 | K27: 85 | L27: 41 | M27: 0.48235294 | N27: 0 | S27: 4028 | T27: 22000.33 | U27: 13905.94 | V27: 0.6320787 | Y27: 4028 | Z27: 10 | AA27: 29 | AD27: 4028 | AE27: 24 | AG27: =SUMIF(CLIENTES!$C:$C,VAREJO!$C27,CLIENTES!$L:$L) -> 0 | AH27: =SUMIF(CLIENTES!$C:$C,VAREJO!$C27,CLIENTES!$M:$M) -> 0 | AJ27: =IF(G27>=100%,2,0) -> 0 | AK27: =IF(J27>=100%,2,0) -> 0 | AL27: =IF(M27>=100%,2,0) -> 0 | AM27: =IF(P27>=100%,2,0) -> 0 | AO27: =IF($V27>=100%,10,0) -> 0 | AQ27: =AA27 -> 29 | AR27: =$AE27 -> 24 | AT27: =Tabela3[[#This Row],[BARRACA MONTADA]]*5 -> 0 | AU27: =Tabela3[[#This Row],[PONTO EXTRA]]*5 -> 0 | AW27: =SUM(Tabela35[[#This Row],[POSI ABRIL]:[PONTO EXTRA]]) -> 53 | AX27: =_xlfn.RANK.EQ(Tabela35[[#This Row],[TOTAL]],Tabela35[TOTAL],0)& "º" -> 38º | AY27: =COUNTA(_xlfn.UNIQUE(_xlfn.VSTACK(AD27,Y27,S27,C27))) -> 1
C28: 4029 | D28: FLORIPA-SUL M | E28: 59 | F28: 65 | G28: 1.1016949 | H28: 69 | I28: 76 | J28: 1.1014493 | K28: 69 | L28: 66 | M28: 0.95652174 | N28: 0 | S28: 4029 | T28: 33000 | U28: 25555.06 | V28: 0.77439576 | Y28: 4029 | Z28: 6 | AA28: 60 | AD28: 4029 | AE28: 51 | AG28: =SUMIF(CLIENTES!$C:$C,VAREJO!$C28,CLIENTES!$L:$L) -> 0 | AH28: =SUMIF(CLIENTES!$C:$C,VAREJO!$C28,CLIENTES!$M:$M) -> 0 | AJ28: =IF(G28>=100%,2,0) -> 2 | AK28: =IF(J28>=100%,2,0) -> 2 | AL28: =IF(M28>=100%,2,0) -> 0 | AM28: =IF(P28>=100%,2,0) -> 0 | AO28: =IF($V28>=100%,10,0) -> 0 | AQ28: =AA28 -> 60 | AR28: =$AE28 -> 51 | AT28: =Tabela3[[#This Row],[BARRACA MONTADA]]*5 -> 0 | AU28: =Tabela3[[#This Row],[PONTO EXTRA]]*5 -> 0 | AW28: =SUM(Tabela35[[#This Row],[POSI ABRIL]:[PONTO EXTRA]]) -> 115 | AX28: =_xlfn.RANK.EQ(Tabela35[[#This Row],[TOTAL]],Tabela35[TOTAL],0)& "º" -> 10º | AY28: =COUNTA(_xlfn.UNIQUE(_xlfn.VSTACK(AD28,Y28,S28,C28))) -> 1
C29: 4030 | D29: FLP-CONV-CONT | E29: 71 | F29: 80 | G29: 1.1267606 | H29: 81 | I29: 89 | J29: 1.0987654 | K29: 82 | L29: 60 | M29: 0.73170732 | N29: 0 | S29: 4030 | T29: 33500.48 | U29: 17906.75 | V29: 0.53452219 | Y29: 4030 | Z29: 1 | AA29: 44 | AD29: 4030 | AE29: 40 | AG29: =SUMIF(CLIENTES!$C:$C,VAREJO!$C29,CLIENTES!$L:$L) -> 0 | AH29: =SUMIF(CLIENTES!$C:$C,VAREJO!$C29,CLIENTES!$M:$M) -> 0 | AJ29: =IF(G29>=100%,2,0) -> 2 | AK29: =IF(J29>=100%,2,0) -> 2 | AL29: =IF(M29>=100%,2,0) -> 0 | AM29: =IF(P29>=100%,2,0) -> 0 | AO29: =IF($V29>=100%,10,0) -> 0 | AQ29: =AA29 -> 44 | AR29: =$AE29 -> 40 | AT29: =Tabela3[[#This Row],[BARRACA MONTADA]]*5 -> 0 | AU29: =Tabela3[[#This Row],[PONTO EXTRA]]*5 -> 0 | AW29: =SUM(Tabela35[[#This Row],[POSI ABRIL]:[PONTO EXTRA]]) -> 88 | AX29: =_xlfn.RANK.EQ(Tabela35[[#This Row],[TOTAL]],Tabela35[TOTAL],0)& "º" -> 16º | AY29: =COUNTA(_xlfn.UNIQUE(_xlfn.VSTACK(AD29,Y29,S29,C29))) -> 1
C30: 4038 | D30: FLORIPA-CONT M | E30: 73 | F30: 35 | G30: 0.47945205 | H30: 84 | I30: 39 | J30: 0.46428571 | K30: 85 | L30: 38 | M30: 0.44705882 | N30: 0 | S30: 4038 | T30: 15500.03 | U30: 11676.92 | V30: 0.75334822 | Y30: 4038 | Z30: 4 | AA30: 33 | AD30: 4038 | AE30: 26 | AG30: =SUMIF(CLIENTES!$C:$C,VAREJO!$C30,CLIENTES!$L:$L) -> 0 | AH30: =SUMIF(CLIENTES!$C:$C,VAREJO!$C30,CLIENTES!$M:$M) -> 0 | AJ30: =IF(G30>=100%,2,0) -> 0 | AK30: =IF(J30>=100%,2,0) -> 0 | AL30: =IF(M30>=100%,2,0) -> 0 | AM30: =IF(P30>=100%,2,0) -> 0 | AO30: =IF($V30>=100%,10,0) -> 0 | AQ30: =AA30 -> 33 | AR30: =$AE30 -> 26 | AT30: =Tabela3[[#This Row],[BARRACA MONTADA]]*5 -> 0 | AU30: =Tabela3[[#This Row],[PONTO EXTRA]]*5 -> 0 | AW30: =SUM(Tabela35[[#This Row],[POSI ABRIL]:[PONTO EXTRA]]) -> 59 | AX30: =_xlfn.RANK.EQ(Tabela35[[#This Row],[TOTAL]],Tabela35[TOTAL],0)& "º" -> 36º | AY30: =COUNTA(_xlfn.UNIQUE(_xlfn.VSTACK(AD30,Y30,S30,C30))) -> 1
C31: 4039 | D31: FLORIPA-NORTE M | E31: 56 | F31: 66 | G31: 1.1785714 | H31: 64 | I31: 74 | J31: 1.15625 | K31: 65 | L31: 49 | M31: 0.75384615 | N31: 0 | S31: 4039 | T31: 36999.88 | U31: 17753.26 | V31: 0.47981939 | Y31: 4039 | Z31: 7 | AA31: 51 | AD31: 4039 | AE31: 47 | AG31: =SUMIF(CLIENTES!$C:$C,VAREJO!$C31,CLIENTES!$L:$L) -> 0 | AH31: =SUMIF(CLIENTES!$C:$C,VAREJO!$C31,CLIENTES!$M:$M) -> 0 | AJ31: =IF(G31>=100%,2,0) -> 2 | AK31: =IF(J31>=100%,2,0) -> 2 | AL31: =IF(M31>=100%,2,0) -> 0 | AM31: =IF(P31>=100%,2,0) -> 0 | AO31: =IF($V31>=100%,10,0) -> 0 | AQ31: =AA31 -> 51 | AR31: =$AE31 -> 47 | AT31: =Tabela3[[#This Row],[BARRACA MONTADA]]*5 -> 0 | AU31: =Tabela3[[#This Row],[PONTO EXTRA]]*5 -> 0 | AW31: =SUM(Tabela35[[#This Row],[POSI ABRIL]:[PONTO EXTRA]]) -> 102 | AX31: =_xlfn.RANK.EQ(Tabela35[[#This Row],[TOTAL]],Tabela35[TOTAL],0)& "º" -> 12º | AY31: =COUNTA(_xlfn.UNIQUE(_xlfn.VSTACK(AD31,Y31,S31,C31))) -> 1
C32: 4040 | D32: BIGUACU M | E32: 63 | F32: 54 | G32: 0.85714286 | H32: 73 | I32: 82 | J32: 1.1232877 | K32: 73 | L32: 37 | M32: 0.50684932 | N32: 0 | S32: 4040 | T32: 18499.94 | U32: 19194.6 | V32: 1.0375493 | Y32: 4040 | Z32: 20 | AA32: 40 | AD32: 4040 | AE32: 31 | AG32: =SUMIF(CLIENTES!$C:$C,VAREJO!$C32,CLIENTES!$L:$L) -> 1 | AH32: =SUMIF(CLIENTES!$C:$C,VAREJO!$C32,CLIENTES!$M:$M) -> 0 | AJ32: =IF(G32>=100%,2,0) -> 0 | AK32: =IF(J32>=100%,2,0) -> 2 | AL32: =IF(M32>=100%,2,0) -> 0 | AM32: =IF(P32>=100%,2,0) -> 0 | AO32: =IF($V32>=100%,10,0) -> 10 | AQ32: =AA32 -> 40 | AR32: =$AE32 -> 31 | AT32: =Tabela3[[#This Row],[BARRACA MONTADA]]*5 -> 5 | AU32: =Tabela3[[#This Row],[PONTO EXTRA]]*5 -> 0 | AW32: =SUM(Tabela35[[#This Row],[POSI ABRIL]:[PONTO EXTRA]]) -> 88 | AX32: =_xlfn.RANK.EQ(Tabela35[[#This Row],[TOTAL]],Tabela35[TOTAL],0)& "º" -> 16º | AY32: =COUNTA(_xlfn.UNIQUE(_xlfn.VSTACK(AD32,Y32,S32,C32))) -> 1
C33: 4071 | D33: SAO JOSE M | E33: 66 | F33: 31 | G33: 0.46969697 | H33: 76 | I33: 11 | J33: 0.14473684 | K33: 76 | L33: 5 | M33: 0.065789474 | N33: 0 | S33: 4071 | T33: 24999.24 | U33: 4337.87 | V33: 0.17352008 | Y33: 4071 | AA33: 8 | AD33: 4071 | AE33: 6 | AG33: =SUMIF(CLIENTES!$C:$C,VAREJO!$C33,CLIENTES!$L:$L) -> 0 | AH33: =SUMIF(CLIENTES!$C:$C,VAREJO!$C33,CLIENTES!$M:$M) -> 0 | AJ33: =IF(G33>=100%,2,0) -> 0 | AK33: =IF(J33>=100%,2,0) -> 0 | AL33: =IF(M33>=100%,2,0) -> 0 | AM33: =IF(P33>=100%,2,0) -> 0 | AO33: =IF($V33>=100%,10,0) -> 0 | AQ33: =AA33 -> 8 | AR33: =$AE33 -> 6 | AT33: =Tabela3[[#This Row],[BARRACA MONTADA]]*5 -> 0 | AU33: =Tabela3[[#This Row],[PONTO EXTRA]]*5 -> 0 | AW33: =SUM(Tabela35[[#This Row],[POSI ABRIL]:[PONTO EXTRA]]) -> 14 | AX33: =_xlfn.RANK.EQ(Tabela35[[#This Row],[TOTAL]],Tabela35[TOTAL],0)& "º" -> 53º | AY33: =COUNTA(_xlfn.UNIQUE(_xlfn.VSTACK(AD33,Y33,S33,C33))) -> 1
C34: 4072 | D34: STO AMARO M | E34: 55 | F34: 60 | G34: 1.0909091 | H34: 63 | I34: 64 | J34: 1.015873 | K34: 64 | L34: 38 | M34: 0.59375 | N34: 0 | S34: 4072 | T34: 20000.39 | U34: 18021.88 | V34: 0.90107643 | Y34: 4072 | Z34: 1 | AA34: 36 | AD34: 4072 | AE34: 28 | AG34: =SUMIF(CLIENTES!$C:$C,VAREJO!$C34,CLIENTES!$L:$L) -> 1 | AH34: =SUMIF(CLIENTES!$C:$C,VAREJO!$C34,CLIENTES!$M:$M) -> 0 | AJ34: =IF(G34>=100%,2,0) -> 2 | AK34: =IF(J34>=100%,2,0) -> 2 | AL34: =IF(M34>=100%,2,0) -> 0 | AM34: =IF(P34>=100%,2,0) -> 0 | AO34: =IF($V34>=100%,10,0) -> 0 | AQ34: =AA34 -> 36 | AR34: =$AE34 -> 28 | AT34: =Tabela3[[#This Row],[BARRACA MONTADA]]*5 -> 5 | AU34: =Tabela3[[#This Row],[PONTO EXTRA]]*5 -> 0 | AW34: =SUM(Tabela35[[#This Row],[POSI ABRIL]:[PONTO EXTRA]]) -> 73 | AX34: =_xlfn.RANK.EQ(Tabela35[[#This Row],[TOTAL]],Tabela35[TOTAL],0)& "º" -> 29º | AY34: =COUNTA(_xlfn.UNIQUE(_xlfn.VSTACK(AD34,Y34,S34,C34))) -> 1
B35: LITORAL M | C35: 3988 | D35: BCA M | E35: 97 | F35: 88 | G35: 0.90721649 | H35: 112 | I35: 85 | J35: 0.75892857 | K35: 112 | L35: 67 | M35: 0.59821429 | N35: 0 | R35: LITORAL M | S35: 3988 | T35: 180999.52 | U35: 117746.37 | V35: 0.65053416 | X35: LITORAL M | Y35: 3988 | Z35: 24 | AA35: 72 | AC35: LITORAL M | AD35: 3988 | AE35: 48 | AG35: =SUMIF(CLIENTES!$C:$C,VAREJO!$C35,CLIENTES!$L:$L) -> 1 | AH35: =SUMIF(CLIENTES!$C:$C,VAREJO!$C35,CLIENTES!$M:$M) -> 1 | AJ35: =IF(G35>=100%,2,0) -> 0 | AK35: =IF(J35>=100%,2,0) -> 0 | AL35: =IF(M35>=100%,2,0) -> 0 | AM35: =IF(P35>=100%,2,0) -> 0 | AO35: =IF($V35>=100%,10,0) -> 0 | AQ35: =AA35 -> 72 | AR35: =$AE35 -> 48 | AT35: =Tabela3[[#This Row],[BARRACA MONTADA]]*5 -> 5 | AU35: =Tabela3[[#This Row],[PONTO EXTRA]]*5 -> 5 | AW35: =SUM(Tabela35[[#This Row],[POSI ABRIL]:[PONTO EXTRA]]) -> 130 | AX35: =_xlfn.RANK.EQ(Tabela35[[#This Row],[TOTAL]],Tabela35[TOTAL],0)& "º" -> 5º | AY35: =COUNTA(_xlfn.UNIQUE(_xlfn.VSTACK(AD35,Y35,S35,C35))) -> 1
C36: 3989 | D36: PICARRAS M | E36: 89 | F36: 104 | G36: 1.1685393 | H36: 102 | I36: 110 | J36: 1.0784314 | K36: 103 | L36: 77 | M36: 0.74757282 | N36: 0 | S36: 3989 | T36: 85499.91 | U36: 59594.73 | V36: 0.69701512 | Y36: 3989 | Z36: 34 | AA36: 42 | AD36: 3989 | AE36: 38 | AG36: =SUMIF(CLIENTES!$C:$C,VAREJO!$C36,CLIENTES!$L:$L) -> 5 | AH36: =SUMIF(CLIENTES!$C:$C,VAREJO!$C36,CLIENTES!$M:$M) -> 0 | AJ36: =IF(G36>=100%,2,0) -> 2 | AK36: =IF(J36>=100%,2,0) -> 2 | AL36: =IF(M36>=100%,2,0) -> 0 | AM36: =IF(P36>=100%,2,0) -> 0 | AO36: =IF($V36>=100%,10,0) -> 0 | AQ36: =AA36 -> 42 | AR36: =$AE36 -> 38 | AT36: =Tabela3[[#This Row],[BARRACA MONTADA]]*5 -> 25 | AU36: =Tabela3[[#This Row],[PONTO EXTRA]]*5 -> 0 | AW36: =SUM(Tabela35[[#This Row],[POSI ABRIL]:[PONTO EXTRA]]) -> 109 | AX36: =_xlfn.RANK.EQ(Tabela35[[#This Row],[TOTAL]],Tabela35[TOTAL],0)& "º" -> 11º | AY36: =COUNTA(_xlfn.UNIQUE(_xlfn.VSTACK(AD36,Y36,S36,C36))) -> 1
C37: 3990 | D37: TIJUCAS M | E37: 82 | F37: 93 | G37: 1.1341463 | H37: 95 | I37: 104 | J37: 1.0947368 | K37: 95 | L37: 60 | M37: 0.63157895 | N37: 0 | S37: 3990 | T37: 43000.7 | U37: 34754.52 | V37: 0.80823149 | Y37: 3990 | Z37: 32 | AA37: 45 | AD37: 3990 | AE37: 34 | AG37: =SUMIF(CLIENTES!$C:$C,VAREJO!$C37,CLIENTES!$L:$L) -> 1 | AH37: =SUMIF(CLIENTES!$C:$C,VAREJO!$C37,CLIENTES!$M:$M) -> 0 | AJ37: =IF(G37>=100%,2,0) -> 2 | AK37: =IF(J37>=100%,2,0) -> 2 | AL37: =IF(M37>=100%,2,0) -> 0 | AM37: =IF(P37>=100%,2,0) -> 0 | AO37: =IF($V37>=100%,10,0) -> 0 | AQ37: =AA37 -> 45 | AR37: =$AE37 -> 34 | AT37: =Tabela3[[#This Row],[BARRACA MONTADA]]*5 -> 5 | AU37: =Tabela3[[#This Row],[PONTO EXTRA]]*5 -> 0 | AW37: =SUM(Tabela35[[#This Row],[POSI ABRIL]:[PONTO EXTRA]]) -> 88 | AX37: =_xlfn.RANK.EQ(Tabela35[[#This Row],[TOTAL]],Tabela35[TOTAL],0)& "º" -> 16º | AY37: =COUNTA(_xlfn.UNIQUE(_xlfn.VSTACK(AD37,Y37,S37,C37))) -> 1
C38: 3995 | D38: CAMBORIU M | E38: 75 | F38: 81 | G38: 1.08 | H38: 87 | I38: 71 | J38: 0.81609195 | K38: 87 | L38: 26 | M38: 0.29885057 | N38: 0 | S38: 3995 | T38: 33999.97 | U38: 24104.33 | V38: 0.70895151 | Y38: 3995 | Z38: 26 | AA38: 37 | AD38: 3995 | AE38: 26 | AG38: =SUMIF(CLIENTES!$C:$C,VAREJO!$C38,CLIENTES!$L:$L) -> 0 | AH38: =SUMIF(CLIENTES!$C:$C,VAREJO!$C38,CLIENTES!$M:$M) -> 0 | AJ38: =IF(G38>=100%,2,0) -> 2 | AK38: =IF(J38>=100%,2,0) -> 0 | AL38: =IF(M38>=100%,2,0) -> 0 | AM38: =IF(P38>=100%,2,0) -> 0 | AO38: =IF($V38>=100%,10,0) -> 0 | AQ38: =AA38 -> 37 | AR38: =$AE38 -> 26 | AT38: =Tabela3[[#This Row],[BARRACA MONTADA]]*5 -> 0 | AU38: =Tabela3[[#This Row],[PONTO EXTRA]]*5 -> 0 | AW38: =SUM(Tabela35[[#This Row],[POSI ABRIL]:[PONTO EXTRA]]) -> 65 | AX38: =_xlfn.RANK.EQ(Tabela35[[#This Row],[TOTAL]],Tabela35[TOTAL],0)& "º" -> 33º | AY38: =COUNTA(_xlfn.UNIQUE(_xlfn.VSTACK(AD38,Y38,S38,C38))) -> 1
C39: 3997 | D39: BRUSQUE M | E39: 90 | F39: 82 | G39: 0.91111111 | H39: 103 | I39: 105 | J39: 1.0194175 | K39: 104 | L39: 70 | M39: 0.67307692 | N39: 0 | S39: 3997 | T39: 71500.33 | U39: 68560.54 | V39: 0.95888425 | Y39: 3997 | Z39: 16 | AA39: 33 | AD39: 3997 | AE39: 27 | AG39: =SUMIF(CLIENTES!$C:$C,VAREJO!$C39,CLIENTES!$L:$L) -> 3 | AH39: =SUMIF(CLIENTES!$C:$C,VAREJO!$C39,CLIENTES!$M:$M) -> 0 | AJ39: =IF(G39>=100%,2,0) -> 0 | AK39: =IF(J39>=100%,2,0) -> 2 | AL39: =IF(M39>=100%,2,0) -> 0 | AM39: =IF(P39>=100%,2,0) -> 0 | AO39: =IF($V39>=100%,10,0) -> 0 | AQ39: =AA39 -> 33 | AR39: =$AE39 -> 27 | AT39: =Tabela3[[#This Row],[BARRACA MONTADA]]*5 -> 15 | AU39: =Tabela3[[#This Row],[PONTO EXTRA]]*5 -> 0 | AW39: =SUM(Tabela35[[#This Row],[POSI ABRIL]:[PONTO EXTRA]]) -> 77 | AX39: =_xlfn.RANK.EQ(Tabela35[[#This Row],[TOTAL]],Tabela35[TOTAL],0)& "º" -> 25º | AY39: =COUNTA(_xlfn.UNIQUE(_xlfn.VSTACK(AD39,Y39,S39,C39))) -> 1
C40: 3999 | D40: NAVEGANTES M | E40: 70 | F40: 73 | G40: 1.0428571 | H40: 80 | I40: 74 | J40: 0.925 | K40: 81 | L40: 53 | M40: 0.65432099 | N40: 0 | S40: 3999 | T40: 26000.21 | U40: 16690.35 | V40: 0.64193135 | Y40: 3999 | Z40: 18 | AA40: 18 | AD40: 3999 | AE40: 16 | AG40: =SUMIF(CLIENTES!$C:$C,VAREJO!$C40,CLIENTES!$L:$L) -> 0 | AH40: =SUMIF(CLIENTES!$C:$C,VAREJO!$C40,CLIENTES!$M:$M) -> 0 | AJ40: =IF(G40>=100%,2,0) -> 2 | AK40: =IF(J40>=100%,2,0) -> 0 | AL40: =IF(M40>=100%,2,0) -> 0 | AM40: =IF(P40>=100%,2,0) -> 0 | AO40: =IF($V40>=100%,10,0) -> 0 | AQ40: =AA40 -> 18 | AR40: =$AE40 -> 16 | AT40: =Tabela3[[#This Row],[BARRACA MONTADA]]*5 -> 0 | AU40: =Tabela3[[#This Row],[PONTO EXTRA]]*5 -> 0 | AW40: =SUM(Tabela35[[#This Row],[POSI ABRIL]:[PONTO EXTRA]]) -> 36 | AX40: =_xlfn.RANK.EQ(Tabela35[[#This Row],[TOTAL]],Tabela35[TOTAL],0)& "º" -> 47º | AY40: =COUNTA(_xlfn.UNIQUE(_xlfn.VSTACK(AD40,Y40,S40,C40))) -> 1
C41: 4000 | D41: BCA CONV | E41: 67 | F41: 80 | G41: 1.1940299 | H41: 77 | I41: 85 | J41: 1.1038961 | K41: 77 | L41: 66 | M41: 0.85714286 | N41: 0 | S41: 4000 | T41: 68500.42 | U41: 48009.7 | V41: 0.70086724 | Y41: 4000 | Z41: 35 | AA41: 65 | AD41: 4000 | AE41: 47 | AG41: =SUMIF(CLIENTES!$C:$C,VAREJO!$C41,CLIENTES!$L:$L) -> 4 | AH41: =SUMIF(CLIENTES!$C:$C,VAREJO!$C41,CLIENTES!$M:$M) -> 0 | AJ41: =IF(G41>=100%,2,0) -> 2 | AK41: =IF(J41>=100%,2,0) -> 2 | AL41: =IF(M41>=100%,2,0) -> 0 | AM41: =IF(P41>=100%,2,0) -> 0 | AO41: =IF($V41>=100%,10,0) -> 0 | AQ41: =AA41 -> 65 | AR41: =$AE41 -> 47 | AT41: =Tabela3[[#This Row],[BARRACA MONTADA]]*5 -> 20 | AU41: =Tabela3[[#This Row],[PONTO EXTRA]]*5 -> 0 | AW41: =SUM(Tabela35[[#This Row],[POSI ABRIL]:[PONTO EXTRA]]) -> 136 | AX41: =_xlfn.RANK.EQ(Tabela35[[#This Row],[TOTAL]],Tabela35[TOTAL],0)& "º" -> 1º | AY41: =COUNTA(_xlfn.UNIQUE(_xlfn.VSTACK(AD41,Y41,S41,C41))) -> 1
C42: 4001 | D42: ITAJAI-NORTE M | E42: 58 | F42: 66 | G42: 1.137931 | H42: 67 | I42: 69 | J42: 1.0298507 | K42: 67 | L42: 44 | M42: 0.65671642 | N42: 0 | S42: 4001 | T42: 31500.55 | U42: 26286.27 | V42: 0.83447019 | Y42: 4001 | Z42: 14 | AA42: 49 | AD42: 4001 | AE42: 39 | AG42: =SUMIF(CLIENTES!$C:$C,VAREJO!$C42,CLIENTES!$L:$L) -> 7 | AH42: =SUMIF(CLIENTES!$C:$C,VAREJO!$C42,CLIENTES!$M:$M) -> 0 | AJ42: =IF(G42>=100%,2,0) -> 2 | AK42: =IF(J42>=100%,2,0) -> 2 | AL42: =IF(M42>=100%,2,0) -> 0 | AM42: =IF(P42>=100%,2,0) -> 0 | AO42: =IF($V42>=100%,10,0) -> 0 | AQ42: =AA42 -> 49 | AR42: =$AE42 -> 39 | AT42: =Tabela3[[#This Row],[BARRACA MONTADA]]*5 -> 35 | AU42: =Tabela3[[#This Row],[PONTO EXTRA]]*5 -> 0 | AW42: =SUM(Tabela35[[#This Row],[POSI ABRIL]:[PONTO EXTRA]]) -> 127 | AX42: =_xlfn.RANK.EQ(Tabela35[[#This Row],[TOTAL]],Tabela35[TOTAL],0)& "º" -> 6º | AY42: =COUNTA(_xlfn.UNIQUE(_xlfn.VSTACK(AD42,Y42,S42,C42))) -> 1
C43: 4024 | D43: ITAJAI CONV | E43: 67 | F43: 68 | G43: 1.0149254 | H43: 77 | I43: 57 | J43: 0.74025974 | K43: 77 | L43: 62 | M43: 0.80519481 | N43: 0 | S43: 4024 | T43: 53000.39 | U43: 31186.69 | V43: 0.58842378 | Y43: 4024 | Z43: 4 | AA43: 43 | AD43: 4024 | AE43: 39 | AG43: =SUMIF(CLIENTES!$C:$C,VAREJO!$C43,CLIENTES!$L:$L) -> 1 | AH43: =SUMIF(CLIENTES!$C:$C,VAREJO!$C43,CLIENTES!$M:$M) -> 0 | AJ43: =IF(G43>=100%,2,0) -> 2 | AK43: =IF(J43>=100%,2,0) -> 0 | AL43: =IF(M43>=100%,2,0) -> 0 | AM43: =IF(P43>=100%,2,0) -> 0 | AO43: =IF($V43>=100%,10,0) -> 0 | AQ43: =AA43 -> 43 | AR43: =$AE43 -> 39 | AT43: =Tabela3[[#This Row],[BARRACA MONTADA]]*5 -> 5 | AU43: =Tabela3[[#This Row],[PONTO EXTRA]]*5 -> 0 | AW43: =SUM(Tabela35[[#This Row],[POSI ABRIL]:[PONTO EXTRA]]) -> 89 | AX43: =_xlfn.RANK.EQ(Tabela35[[#This Row],[TOTAL]],Tabela35[TOTAL],0)& "º" -> 15º | AY43: =COUNTA(_xlfn.UNIQUE(_xlfn.VSTACK(AD43,Y43,S43,C43))) -> 1
...

Sheet MÉDIAS CONTAS
E4: MÊS | F4: Valores
E5: ABRIL | H5: MAIO | K5: JUNHO | N5: JULHO | Q5: Total META | R5: Total R$ | S5: Total % R
D6: EQUIPE | E6: META | F6: R$ | G6: % R | H6: META | I6: R$ | J6: % R | K6: META | L6: R$ | M6: % R | N6: META | O6: R$ | P6: % R
D7: FLP-SUL MC/KA D | E7: 480606.06 | F7: 421850.35 | G7: 0.87774663 | H7: 1330910 | I7: 1064643 | J7: 0.79993614 | K7: 628485 | L7: 748157.77 | M7: 1.1904147 | N7: 0 | Q7: 2440001.1 | R7: 2234651.1 | S7: 0.91584023
D8: FLP-SUL MC/KA M | E8: 102522.73 | F8: 139869.44 | G8: 1.3642774 | H8: 283909 | I8: 382496.17 | J8: 1.3472492 | K8: 134069 | L8: 89410.83 | M8: 0.6669016 | N8: 0 | Q8: 520500.73 | R8: 611776.44 | S8: 1.1753613
D9: NORTE MC/KA D | E9: 68053.03 | F9: 127159.6 | G9: 1.8685369 | H9: 188456 | I9: 186454.44 | J9: 0.98937917 | K9: 88991 | L9: 45351.23 | M9: 0.50961592 | N9: 0 | Q9: 345500.03 | R9: 358965.27 | S9: 1.0389732
D10: NORTE MC/KA M | E10: 248378.78 | F10: 183649.26 | G10: 0.73939191 | H10: 687819 | I10: 681417.28 | J10: 0.99069273 | K10: 324803 | L10: 153562.58 | M10: 0.47278683 | N10: 0 | Q10: 1261000.8 | R10: 1018629.1 | S10: 0.8077942
B12: GRANDES CONTAS
B13: GRUPO | C13: GRANDES CONTAS
E15: MÊS | F15: Valores
E16: ABRIL | H16: MAIO | K16: JUNHO | N16: JULHO | Q16: Total META | R16: Total R$ | S16: Total % R
B17: EQUIPE | C17: ID | D17: ÁREA | E17: META | F17: R$ | G17: % R | H17: META | I17: R$ | J17: % R | K17: META | L17: R$ | M17: % R | N17: META | O17: R$ | P17: % R
B18: FLP-SUL MC/KA D | C18: 224 | D18: KA-CRC PC | E18: 419840.91 | F18: 382686.02 | G18: 0.91150245 | H18: 1162636 | I18: 889738.63 | J18: 0.76527703 | K18: 549023 | L18: 675775.68 | M18: 1.2308695 | N18: 0 | Q18: 2131499.9 | R18: 1948200.3 | S18: 0.91400442
C19: 3861 | D19: MC-PLH PC | E19: 60765.15 | F19: 41409.1 | G19: 0.68146133 | H19: 168274 | I19: 176850.87 | J19: 1.0509697 | K19: 79462 | L19: 72678.28 | M19: 0.91462938 | N19: 0 | Q19: 308501.15 | R19: 290938.25 | S19: 0.94307023
B20: NORTE MC/KA D | C20: 179 | D20: KA-BRQ | E20: 68053.03 | F20: 128009.7 | G20: 1.8810287 | H20: 188456 | I20: 186605.8 | J20: 0.99018232 | K20: 88991 | L20: 45381.7 | M20: 0.50995831 | N20: 0 | Q20: 345500.03 | R20: 359997.2 | S20: 1.04196
B21: NORTE MC/KA M | C21: 417 | D21: KA-ROS | E21: 39393.94 | F21: 52563.46 | G21: 1.3343032 | H21: 109092 | I21: 95503.58 | J21: 0.87544073 | K21: 51515 | L21: 21184.49 | M21: 0.41122954 | N21: 0 | Q21: 200000.94 | R21: 169251.53 | S21: 0.84625367
C22: 5009 | D22: KA-BNU M | E22: 108333.33 | F22: 79964.61 | G22: 0.73813488 | H22: 300000 | I22: 369673.91 | J22: 1.2322464 | K22: 141667 | L22: 89730.68 | M22: 0.63339154 | N22: 0 | Q22: 550000.33 | R22: 539369.2 | S22: 0.98067068
B26: RANKING MÉDIAS CONTAS
B27: GRUPO | C27: MÉDIAS CONTAS
E29: MÊS | F29: Valores
E30: ABRIL | H30: MAIO | K30: JUNHO | N30: JULHO | Q30: Total META | R30: Total R$ | S30: Total % R | U30: MERCHANDISING | Z30: PONTUAÇÕES RANKING | AJ30: RANKING
B31: EQUIPE | C31: ID | D31: ÁREA | E31: META | F31: R$ | G31: % R | H31: META | I31: R$ | J31: % R | K31: META | L31: R$ | M31: % R | N31: META | O31: R$ | P31: % R | U31: BARRACA MONTADA | V31: PONTO EXTRA | W31: LINHA ZERO AÇUCAR | X31: LANÇAMENTOS | Z31: R$ ABRIL | AA31: R$ MAIO | AB31: R$ JUNHO | AC31: R$ JULHO | AD31: R$ TOTAL | AE31: BARRACA MONTADA | AF31: PONTO EXTRA | AG31: LINHA ZERO AÇUCAR | AH31: LANÇAMENTOS | AJ31: TOTAL | AK31: RANKING
B32: FLP-SUL MC/KA M | C32: 307 | D32: MC-ARA M | E32: 2856.06 | F32: 3163.19 | G32: 1.1075363 | H32: 7909 | I32: 23722.78 | J32: 2.9994664 | K32: 3735 | L32: 6169.57 | M32: 1.651826 | N32: 0 | Q32: 14500.06 | R32: 33055.54 | S32: 2.279683 | U32: =SUMIF(CLIENTES!$C:$C,'MÉDIAS CONTAS'!$C32,CLIENTES!$L:$L) -> 1 | V32: =SUMIF(CLIENTES!$C:$C,'MÉDIAS CONTAS'!$C32,CLIENTES!$M:$M) -> 1 | W32: =SUMIF(CLIENTES!$C:$C,'MÉDIAS CONTAS'!$C32,CLIENTES!$N:$N) -> 0 | X32: =SUMIF(CLIENTES!$C:$C,'MÉDIAS CONTAS'!$C32,CLIENTES!$O:$O) -> 0 | Z32: =IF(G32>=100%,2,0) -> 2 | AA32: =IF(J32>=100%,2,0) -> 2 | AB32: =IF(M32>=100%,2,0) -> 2 | AC32: =IF(P32>=100%,2,0) -> 0 | AD32: =IF(S32>=100%,2,0) -> 2 | AE32: =Tabela12[[#This Row],[BARRACA MONTADA]]*5 -> 5 | AF32: =Tabela12[[#This Row],[PONTO EXTRA]]*5 -> 5 | AG32: =Tabela12[[#This Row],[LINHA ZERO AÇUCAR]]*2 -> 0 | AH32: =Tabela12[[#This Row],[LANÇAMENTOS]]*3 -> 0 | AJ32: =SUM(Tabela13[#This Row]) -> 18 | AK32: =_xlfn.RANK.EQ(AJ32,$AJ$32:$AJ$44,0)& "º" -> 6º
C33: 383 | D33: MC-TBCR M | E33: 40575.76 | F33: 57361.39 | G33: 1.4136862 | H33: 112364 | I33: 106648.83 | J33: 0.949137 | K33: 53061 | L33: 31447.42 | M33: 0.59266542 | N33: 0 | Q33: 206000.76 | R33: 195457.64 | S33: 0.94881999 | U33: =SUMIF(CLIENTES!$C:$C,'MÉDIAS CONTAS'!$C33,CLIENTES!$L:$L) -> 0 | V33: =SUMIF(CLIENTES!$C:$C,'MÉDIAS CONTAS'!$C33,CLIENTES!$M:$M) -> 1 | W33: =SUMIF(CLIENTES!$C:$C,'MÉDIAS CONTAS'!$C33,CLIENTES!$N:$N) -> 0 | X33: =SUMIF(CLIENTES!$C:$C,'MÉDIAS CONTAS'!$C33,CLIENTES!$O:$O) -> 0 | Z33: =IF(G33>=100%,2,0) -> 2 | AA33: =IF(J33>=100%,2,0) -> 0 | AB33: =IF(M33>=100%,2,0) -> 0 | AC33: =IF(P33>=100%,2,0) -> 0 | AD33: =IF(S33>=100%,2,0) -> 0 | AE33: =Tabela12[[#This Row],[BARRACA MONTADA]]*5 -> 0 | AF33: =Tabela12[[#This Row],[PONTO EXTRA]]*5 -> 5 | AG33: =Tabela12[[#This Row],[LINHA ZERO AÇUCAR]]*2 -> 0 | AH33: =Tabela12[[#This Row],[LANÇAMENTOS]]*3 -> 0 | AJ33: =SUM(Tabela13[#This Row]) -> 7 | AK33: =_xlfn.RANK.EQ(AJ33,$AJ$32:$AJ$44,0)& "º" -> 9º
C34: 3928 | D34: MC-FLP M | E34: 12803.03 | F34: 13577.85 | G34: 1.0605185 | H34: 35455 | I34: 35927.8 | J34: 1.0133352 | K34: 16742 | L34: 5479.45 | M34: 0.32728766 | N34: 0 | Q34: 65000.03 | R34: 54985.1 | S34: 0.84592422 | U34: =SUMIF(CLIENTES!$C:$C,'MÉDIAS CONTAS'!$C34,CLIENTES!$L:$L) -> 0 | V34: =SUMIF(CLIENTES!$C:$C,'MÉDIAS CONTAS'!$C34,CLIENTES!$M:$M) -> 0 | W34: =SUMIF(CLIENTES!$C:$C,'MÉDIAS CONTAS'!$C34,CLIENTES!$N:$N) -> 0 | X34: =SUMIF(CLIENTES!$C:$C,'MÉDIAS CONTAS'!$C34,CLIENTES!$O:$O) -> 0 | Z34: =IF(G34>=100%,2,0) -> 2 | AA34: =IF(J34>=100%,2,0) -> 2 | AB34: =IF(M34>=100%,2,0) -> 0 | AC34: =IF(P34>=100%,2,0) -> 0 | AD34: =IF(S34>=100%,2,0) -> 0 | AE34: =Tabela12[[#This Row],[BARRACA MONTADA]]*5 -> 0 | AF34: =Tabela12[[#This Row],[PONTO EXTRA]]*5 -> 0 | AG34: =Tabela12[[#This Row],[LINHA ZERO AÇUCAR]]*2 -> 0 | AH34: =Tabela12[[#This Row],[LANÇAMENTOS]]*3 -> 0 | AJ34: =SUM(Tabela13[#This Row]) -> 4 | AK34: =_xlfn.RANK.EQ(AJ34,$AJ$32:$AJ$44,0)& "º" -> 12º
C35: 3942 | D35: MC-IMB M | E35: 9651.52 | F35: 29489.11 | G35: 3.0553851 | H35: 26727 | I35: 102442.89 | J35: 3.8329364 | K35: 12621 | L35: -2489.35 | M35: -0.19723873 | N35: 0 | Q35: 48999.52 | R35: 129442.65 | S35: 2.6417126 | U35: =SUMIF(CLIENTES!$C:$C,'MÉDIAS CONTAS'!$C35,CLIENTES!$L:$L) -> 12 | V35: =SUMIF(CLIENTES!$C:$C,'MÉDIAS CONTAS'!$C35,CLIENTES!$M:$M) -> 2 | W35: =SUMIF(CLIENTES!$C:$C,'MÉDIAS CONTAS'!$C35,CLIENTES!$N:$N) -> 0 | X35: =SUMIF(CLIENTES!$C:$C,'MÉDIAS CONTAS'!$C35,CLIENTES!$O:$O) -> 0 | Z35: =IF(G35>=100%,2,0) -> 2 | AA35: =IF(J35>=100%,2,0) -> 2 | AB35: =IF(M35>=100%,2,0) -> 0 | AC35: =IF(P35>=100%,2,0) -> 0 | AD35: =IF(S35>=100%,2,0) -> 2 | AE35: =Tabela12[[#This Row],[BARRACA MONTADA]]*5 -> 60 | AF35: =Tabela12[[#This Row],[PONTO EXTRA]]*5 -> 10 | AG35: =Tabela12[[#This Row],[LINHA ZERO AÇUCAR]]*2 -> 0 | AH35: =Tabela12[[#This Row],[LANÇAMENTOS]]*3 -> 0 | AJ35: =SUM(Tabela13[#This Row]) -> 76 | AK35: =_xlfn.RANK.EQ(AJ35,$AJ$32:$AJ$44,0)& "º" -> 1º
C36: 4056 | D36: MC-SJO M | E36: 9848.48 | F36: 4997.84 | G36: 0.50747323 | H36: 27273 | I36: 7899.85 | J36: 0.28965827 | K36: 12879 | L36: 13795.64 | M36: 1.0711732 | N36: 0 | Q36: 50000.48 | R36: 26693.33 | S36: 0.53386147 | U36: =SUMIF(CLIENTES!$C:$C,'MÉDIAS CONTAS'!$C36,CLIENTES!$L:$L) -> 3 | V36: =SUMIF(CLIENTES!$C:$C,'MÉDIAS CONTAS'!$C36,CLIENTES!$M:$M) -> 0 | W36: =SUMIF(CLIENTES!$C:$C,'MÉDIAS CONTAS'!$C36,CLIENTES!$N:$N) -> 0 | X36: =SUMIF(CLIENTES!$C:$C,'MÉDIAS CONTAS'!$C36,CLIENTES!$O:$O) -> 0 | Z36: =IF(G36>=100%,2,0) -> 0 | AA36: =IF(J36>=100%,2,0) -> 0 | AB36: =IF(M36>=100%,2,0) -> 2 | AC36: =IF(P36>=100%,2,0) -> 0 | AD36: =IF(S36>=100%,2,0) -> 0 | AE36: =Tabela12[[#This Row],[BARRACA MONTADA]]*5 -> 15 | AF36: =Tabela12[[#This Row],[PONTO EXTRA]]*5 -> 0 | AG36: =Tabela12[[#This Row],[LINHA ZERO AÇUCAR]]*2 -> 0 | AH36: =Tabela12[[#This Row],[LANÇAMENTOS]]*3 -> 0 | AJ36: =SUM(Tabela13[#This Row]) -> 17 | AK36: =_xlfn.RANK.EQ(AJ36,$AJ$32:$AJ$44,0)& "º" -> 7º
C37: 4065 | D37: MC-LAGES | E37: 10340.91 | F37: 11804.28 | G37: 1.1415127 | H37: 28636 | I37: 27567.37 | J37: 0.96268229 | K37: 13523 | L37: 12256.15 | M37: 0.90631886 | N37: 0 | Q37: 52499.91 | R37: 51627.8 | S37: 0.98338835 | U37: =SUMIF(CLIENTES!$C:$C,'MÉDIAS CONTAS'!$C37,CLIENTES!$L:$L) -> 2 | V37: =SUMIF(CLIENTES!$C:$C,'MÉDIAS CONTAS'!$C37,CLIENTES!$M:$M) -> 0 | W37: =SUMIF(CLIENTES!$C:$C,'MÉDIAS CONTAS'!$C37,CLIENTES!$N:$N) -> 0 | X37: =SUMIF(CLIENTES!$C:$C,'MÉDIAS CONTAS'!$C37,CLIENTES!$O:$O) -> 0 | Z37: =IF(G37>=100%,2,0) -> 2 | AA37: =IF(J37>=100%,2,0) -> 0 | AB37: =IF(M37>=100%,2,0) -> 0 | AC37: =IF(P37>=100%,2,0) -> 0 | AD37: =IF(S37>=100%,2,0) -> 0 | AE37: =Tabela12[[#This Row],[BARRACA MONTADA]]*5 -> 10 | AF37: =Tabela12[[#This Row],[PONTO EXTRA]]*5 -> 0 | AG37: =Tabela12[[#This Row],[LINHA ZERO AÇUCAR]]*2 -> 0 | AH37: =Tabela12[[#This Row],[LANÇAMENTOS]]*3 -> 0 | AJ37: =SUM(Tabela13[#This Row]) -> 12 | AK37: =_xlfn.RANK.EQ(AJ37,$AJ$32:$AJ$44,0)& "º" -> 8º
C38: 4085 | D38: MC-CRC M | E38: 6500 | F38: 12098.36 | G38: 1.8612862 | H38: 18000 | I38: 14189.82 | J38: 0.78832333 | K38: 8500 | L38: 8869.07 | M38: 1.04342 | N38: 0 | Q38: 33000 | R38: 35157.25 | S38: 1.0653712 | U38: =SUMIF(CLIENTES!$C:$C,'MÉDIAS CONTAS'!$C38,CLIENTES!$L:$L) -> 0 | V38: =SUMIF(CLIENTES!$C:$C,'MÉDIAS CONTAS'!$C38,CLIENTES!$M:$M) -> 0 | W38: =SUMIF(CLIENTES!$C:$C,'MÉDIAS CONTAS'!$C38,CLIENTES!$N:$N) -> 0 | X38: =SUMIF(CLIENTES!$C:$C,'MÉDIAS CONTAS'!$C38,CLIENTES!$O:$O) -> 0 | Z38: =IF(G38>=100%,2,0) -> 2 | AA38: =IF(J38>=100%,2,0) -> 0 | AB38: =IF(M38>=100%,2,0) -> 2 | AC38: =IF(P38>=100%,2,0) -> 0 | AD38: =IF(S38>=100%,2,0) -> 2 | AE38: =Tabela12[[#This Row],[BARRACA MONTADA]]*5 -> 0 | AF38: =Tabela12[[#This Row],[PONTO EXTRA]]*5 -> 0 | AG38: =Tabela12[[#This Row],[LINHA ZERO AÇUCAR]]*2 -> 0 | AH38: =Tabela12[[#This Row],[LANÇAMENTOS]]*3 -> 0 | AJ38: =SUM(Tabela13[#This Row]) -> 6 | AK38: =_xlfn.RANK.EQ(AJ38,$AJ$32:$AJ$44,0)& "º" -> 10º
C39: 5005 | D39: MC-BGU M | E39: 9946.97 | F39: 7377.42 | G39: 0.7416751 | H39: 27545 | I39: 64096.83 | J39: 2.326986 | K39: 13008 | L39: 13882.88 | M39: 1.0672571 | N39: 0 | Q39: 50499.97 | R39: 85357.13 | S39: 1.6902412 | U39: =SUMIF(CLIENTES!$C:$C,'MÉDIAS CONTAS'!$C39,CLIENTES!$L:$L) -> 5 | V39: =SUMIF(CLIENTES!$C:$C,'MÉDIAS CONTAS'!$C39,CLIENTES!$M:$M) -> 0 | W39: =SUMIF(CLIENTES!$C:$C,'MÉDIAS CONTAS'!$C39,CLIENTES!$N:$N) -> 0 | X39: =SUMIF(CLIENTES!$C:$C,'MÉDIAS CONTAS'!$C39,CLIENTES!$O:$O) -> 0 | Z39: =IF(G39>=100%,2,0) -> 0 | AA39: =IF(J39>=100%,2,0) -> 2 | AB39: =IF(M39>=100%,2,0) -> 2 | AC39: =IF(P39>=100%,2,0) -> 0 | AD39: =IF(S39>=100%,2,0) -> 2 | AE39: =Tabela12[[#This Row],[BARRACA MONTADA]]*5 -> 25 | AF39: =Tabela12[[#This Row],[PONTO EXTRA]]*5 -> 0 | AG39: =Tabela12[[#This Row],[LINHA ZERO AÇUCAR]]*2 -> 0 | AH39: =Tabela12[[#This Row],[LANÇAMENTOS]]*3 -> 0 | AJ39: =SUM(Tabela13[#This Row]) -> 31 | AK39: =_xlfn.RANK.EQ(AJ39,$AJ$32:$AJ$44,0)& "º" -> 4º
B40: NORTE MC/KA M | C40: 683 | D40: MC-ITPE M | E40: 27772.73 | F40: 8345.14 | G40: 0.30047964 | H40: 76909 | I40: 55580.23 | J40: 0.72267524 | K40: 36318 | L40: 12329.26 | M40: 0.3394807 | N40: 0 | Q40: 140999.73 | R40: 76254.63 | S40: 0.54081401 | U40: =SUMIF(CLIENTES!$C:$C,'MÉDIAS CONTAS'!$C40,CLIENTES!$L:$L) -> 2 | V40: =SUMIF(CLIENTES!$C:$C,'MÉDIAS CONTAS'!$C40,CLIENTES!$M:$M) -> 4 | W40: =SUMIF(CLIENTES!$C:$C,'MÉDIAS CONTAS'!$C40,CLIENTES!$N:$N) -> 0 | X40: =SUMIF(CLIENTES!$C:$C,'MÉDIAS CONTAS'!$C40,CLIENTES!$O:$O) -> 0 | Z40: =IF(G40>=100%,2,0) -> 0 | AA40: =IF(J40>=100%,2,0) -> 0 | AB40: =IF(M40>=100%,2,0) -> 0 | AC40: =IF(P40>=100%,2,0) -> 0 | AD40: =IF(S40>=100%,2,0) -> 0 | AE40: =Tabela12[[#This Row],[BARRACA MONTADA]]*5 -> 10 | AF40: =Tabela12[[#This Row],[PONTO EXTRA]]*5 -> 20 | AG40: =Tabela12[[#This Row],[LINHA ZERO AÇUCAR]]*2 -> 0 | AH40: =Tabela12[[#This Row],[LANÇAMENTOS]]*3 -> 0 | AJ40: =SUM(Tabela13[#This Row]) -> 30 | AK40: =_xlfn.RANK.EQ(AJ40,$AJ$32:$AJ$44,0)& "º" -> 5º
C41: 3147 | D41: MC-BNU M | E41: 9848.48 | F41: 4810.43 | G41: 0.4884439 | H41: 27273 | I41: 11396.51 | J41: 0.41786785 | K41: 12879 | L41: 964.5 | M41: 0.074889355 | N41: 0 | Q41: 50000.48 | R41: 17171.44 | S41: 0.3434255 | U41: =SUMIF(CLIENTES!$C:$C,'MÉDIAS CONTAS'!$C41,CLIENTES!$L:$L) -> 1 | V41: =SUMIF(CLIENTES!$C:$C,'MÉDIAS CONTAS'!$C41,CLIENTES!$M:$M) -> 0 | W41: =SUMIF(CLIENTES!$C:$C,'MÉDIAS CONTAS'!$C41,CLIENTES!$N:$N) -> 0 | X41: =SUMIF(CLIENTES!$C:$C,'MÉDIAS CONTAS'!$C41,CLIENTES!$O:$O) -> 0 | Z41: =IF(G41>=100%,2,0) -> 0 | AA41: =IF(J41>=100%,2,0) -> 0 | AB41: =IF(M41>=100%,2,0) -> 0 | AC41: =IF(P41>=100%,2,0) -> 0 | AD41: =IF(S41>=100%,2,0) -> 0 | AE41: =Tabela12[[#This Row],[BARRACA MONTADA]]*5 -> 5 | AF41: =Tabela12[[#This Row],[PONTO EXTRA]]*5 -> 0 | AG41: =Tabela12[[#This Row],[LINHA ZERO AÇUCAR]]*2 -> 0 | AH41: =Tabela12[[#This Row],[LANÇAMENTOS]]*3 -> 0 | AJ41: =SUM(Tabela13[#This Row]) -> 5 | AK41: =_xlfn.RANK.EQ(AJ41,$AJ$32:$AJ$44,0)& "º" -> 11º
C42: 3221 | D42: MC-JLLE M | E42: 29545.45 | F42: 12598.06 | G42: 0.42639594 | H42: 81818 | I42: 38149.06 | J42: 0.46626733 | K42: 38636 | L42: 10852.02 | M42: 0.28087846 | N42: 0 | Q42: 149999.45 | R42: 61599.14 | S42: 0.41066244 | U42: =SUMIF(CLIENTES!$C:$C,'MÉDIAS CONTAS'!$C42,CLIENTES!$L:$L) -> 0 | V42: =SUMIF(CLIENTES!$C:$C,'MÉDIAS CONTAS'!$C42,CLIENTES!$M:$M) -> 0 | W42: =SUMIF(CLIENTES!$C:$C,'MÉDIAS CONTAS'!$C42,CLIENTES!$N:$N) -> 0 | X42: =SUMIF(CLIENTES!$C:$C,'MÉDIAS CONTAS'!$C42,CLIENTES!$O:$O) -> 0 | Z42: =IF(G42>=100%,2,0) -> 0 | AA42: =IF(J42>=100%,2,0) -> 0 | AB42: =IF(M42>=100%,2,0) -> 0 | AC42: =IF(P42>=100%,2,0) -> 0 | AD42: =IF(S42>=100%,2,0) -> 0 | AE42: =Tabela12[[#This Row],[BARRACA MONTADA]]*5 -> 0 | AF42: =Tabela12[[#This Row],[PONTO EXTRA]]*5 -> 0 | AG42: =Tabela12[[#This Row],[LINHA ZERO AÇUCAR]]*2 -> 0 | AH42: =Tabela12[[#This Row],[LANÇAMENTOS]]*3 -> 0 | AJ42: =SUM(Tabela13[#This Row]) -> 0 | AK42: =_xlfn.RANK.EQ(AJ42,$AJ$32:$AJ$44,0)& "º" -> 13º
C43: 4067 | D43: MC-ITJ M | E43: 22651.52 | F43: 13030.89 | G43: 0.57527663 | H43: 62727 | I43: 67152.1 | J43: 1.0705454 | K43: 29621 | L43: 18524.67 | M43: 0.62538976 | N43: 0 | Q43: 114999.52 | R43: 98707.66 | S43: 0.85833106 | U43: =SUMIF(CLIENTES!$C:$C,'MÉDIAS CONTAS'!$C43,CLIENTES!$L:$L) -> 11 | V43: =SUMIF(CLIENTES!$C:$C,'MÉDIAS CONTAS'!$C43,CLIENTES!$M:$M) -> 0 | W43: =SUMIF(CLIENTES!$C:$C,'MÉDIAS CONTAS'!$C43,CLIENTES!$N:$N) -> 0 | X43: =SUMIF(CLIENTES!$C:$C,'MÉDIAS CONTAS'!$C43,CLIENTES!$O:$O) -> 0 | Z43: =IF(G43>=100%,2,0) -> 0 | AA43: =IF(J43>=100%,2,0) -> 2 | AB43: =IF(M43>=100%,2,0) -> 0 | AC43: =IF(P43>=100%,2,0) -> 0 | AD43: =IF(S43>=100%,2,0) -> 0 | AE43: =Tabela12[[#This Row],[BARRACA MONTADA]]*5 -> 55 | AF43: =Tabela12[[#This Row],[PONTO EXTRA]]*5 -> 0 | AG43: =Tabela12[[#This Row],[LINHA ZERO AÇUCAR]]*2 -> 0 | AH43: =Tabela12[[#This Row],[LANÇAMENTOS]]*3 -> 0 | AJ43: =SUM(Tabela13[#This Row]) -> 57 | AK43: =_xlfn.RANK.EQ(AJ43,$AJ$32:$AJ$44,0)& "º" -> 2º
C44: 4096 | D44: MC-SFS M | E44: 10833.33 | F44: 12336.67 | G44: 1.1387699 | H44: 30000 | I44: 43961.89 | J44: 1.4653963 | K44: 14167 | L44: -23.04 | M44: -0.0016263147 | N44: 0 | Q44: 55000.33 | R44: 56275.52 | S44: 1.0231851 | U44: =SUMIF(CLIENTES!$C:$C,'MÉDIAS CONTAS'!$C44,CLIENTES!$L:$L) -> 7 | V44: =SUMIF(CLIENTES!$C:$C,'MÉDIAS CONTAS'!$C44,CLIENTES!$M:$M) -> 0 | W44: =SUMIF(CLIENTES!$C:$C,'MÉDIAS CONTAS'!$C44,CLIENTES!$N:$N) -> 0 | X44: =SUMIF(CLIENTES!$C:$C,'MÉDIAS CONTAS'!$C44,CLIENTES!$O:$O) -> 0 | Z44: =IF(G44>=100%,2,0) -> 2 | AA44: =IF(J44>=100%,2,0) -> 2 | AB44: =IF(M44>=100%,2,0) -> 0 | AC44: =IF(P44>=100%,2,0) -> 0 | AD44: =IF(S44>=100%,2,0) -> 2 | AE44: =Tabela12[[#This Row],[BARRACA MONTADA]]*5 -> 35 | AF44: =Tabela12[[#This Row],[PONTO EXTRA]]*5 -> 0 | AG44: =Tabela12[[#This Row],[LINHA ZERO AÇUCAR]]*2 -> 0 | AH44: =Tabela12[[#This Row],[LANÇAMENTOS]]*3 -> 0 | AJ44: =SUM(Tabela13[#This Row]) -> 41 | AK44: =_xlfn.RANK.EQ(AJ44,$AJ$32:$AJ$44,0)& "º" -> 3º

Sheet CLIENTES
B3: EQUIPE | C3: CÓD | D3: ÁREA | E3: CÓD | F3: RAZÃO | G3: DIA | H3: DATA | I3: POSITIVAÇÃO GERAL | J3: PAÇOCA ZERO | K3: LANÇAMENTOS | L3: BARRACAS(FOTO) | M3: P.EXTRAS(FOTO) | N3: LINHA ZERO(BARRACA) | O3: LANÇAMENTOS(BARRACA)
B4: FLORIPA M | C4: 4026 | D4: FLP-CONV-ILHA | E4: 52245 | F4: POSTO GALO LTDA | G4: Qua | H4: 46176 | I4: 1 | J4: 1
B5: FLORIPA M | C5: 4026 | D5: FLP-CONV-ILHA | E5: 52247 | F5: LS COM SORVETE BOMBONIERE E TABAC LTDA | G5: Sex | H5: 46171
B6: FLORIPA M | C6: 4026 | D6: FLP-CONV-ILHA | E6: 52381 | F6: POSTO GALO LTDA | G6: Ter | H6: 46182 | I6: 1
B7: FLORIPA M | C7: 4026 | D7: FLP-CONV-ILHA | E7: 53111 | F7: CIDINEI JOAO DE SOUZA | G7: Qui | H7: 46170 | I7: 1
B8: FLORIPA M | C8: 4026 | D8: FLP-CONV-ILHA | E8: 55988 | F8: M R MACHADO E CIA LTDA | G8: Qui | H8: 46177
B9: FLORIPA M | C9: 4026 | D9: FLP-CONV-ILHA | E9: 61579 | F9: DM COMERCIO DE ALIMENTOS LTDA | G9: Sex | H9: 46171
B10: FLORIPA M | C10: 4026 | D10: FLP-CONV-ILHA | E10: 62492 | F10: POSTO GALO LTDA | G10: Qua | H10: 46183 | I10: 1
B11: FLORIPA M | C11: 4026 | D11: FLP-CONV-ILHA | E11: 63694 | F11: RESTAURANTE MEDEIROS LTDA | G11: Sex | H11: 46171
B12: FLORIPA M | C12: 4026 | D12: FLP-CONV-ILHA | E12: 66820 | F12: COLONIAL PRODUTOS SERVICOS LTDA | G12: Ter | H12: 46182 | I12: 1
B13: FLORIPA M | C13: 4026 | D13: FLP-CONV-ILHA | E13: 66834 | F13: POSTO GALO LTDA | G13: Qua | H13: 46183 | I13: 1 | J13: 1
B14: FLORIPA M | C14: 4026 | D14: FLP-CONV-ILHA | E14: 67800 | F14: POSTO RIO VERMELHO LTDA | G14: Seg | H14: 46181
B15: FLORIPA M | C15: 4026 | D15: FLP-CONV-ILHA | E15: 69981 | F15: POSTO MARILU LTDA | G15: Seg | H15: 46181
B16: FLORIPA M | C16: 4026 | D16: FLP-CONV-ILHA | E16: 73333 | F16: POSTO RIO VERMELHO LTDA | G16: Seg | H16: 46181
B17: FLORIPA M | C17: 4026 | D17: FLP-CONV-ILHA | E17: 74157 | F17: AVILA COMERCIO DE COMBUSTIVEIS LTDA | G17: Qua | H17: 46176
B18: FLORIPA M | C18: 4026 | D18: FLP-CONV-ILHA | E18: 74763 | F18: VILA RICA COMERCIO DE COMBUSTIVEIS LTDA | G18: Ter | H18: 46182
B19: FLORIPA M | C19: 4026 | D19: FLP-CONV-ILHA | E19: 74844 | F19: COMERCIO DE COMB E LUBRIF INGLESES LTDA | G19: Seg | H19: 46181 | I19: 1
B20: FLORIPA M | C20: 4026 | D20: FLP-CONV-ILHA | E20: 77041 | F20: POSTO GALO LTDA | G20: Ter | H20: 46175 | I20: 1 | J20: 1
B21: FLORIPA M | C21: 4026 | D21: FLP-CONV-ILHA | E21: 77452 | F21: POSTO GALO LTDA | G21: Ter | H21: 46175 | I21: 1 | J21: 1
B22: FLORIPA M | C22: 4026 | D22: FLP-CONV-ILHA | E22: 78038 | F22: POSTO DE SERVICOS ILHA BELA LTDA | G22: Ter | H22: 46182 | I22: 1 | J22: 1
B23: FLORIPA M | C23: 4026 | D23: FLP-CONV-ILHA | E23: 78751 | F23: AUTO POSTO ABAST E SERV 5 ESTRELAS LTDA | G23: Ter | H23: 46182
B24: FLORIPA M | C24: 4026 | D24: FLP-CONV-ILHA | E24: 80510 | F24: VALPAS BOMBONIERE E TABACARIA LTDA | G24: Seg | H24: 46174 | I24: 1
B25: FLORIPA M | C25: 4026 | D25: FLP-CONV-ILHA | E25: 82816 | F25: REAL AUTO POSTO LTDA | G25: Qui | H25: 46170
B26: FLORIPA M | C26: 4026 | D26: FLP-CONV-ILHA | E26: 83279 | F26: FLORIPETRO COM DE COMBUSTIVEIS LTDA | G26: Ter | H26: 46182 | I26: 1 | J26: 1
B27: FLORIPA M | C27: 4026 | D27: FLP-CONV-ILHA | E27: 83948 | F27: NEI SARTOR ME | G27: Qui | H27: 46177
B28: FLORIPA M | C28: 4026 | D28: FLP-CONV-ILHA | E28: 84056 | F28: DELICIAS DO CAMPO LTDA | G28: Qua | H28: 46183
B29: FLORIPA M | C29: 4026 | D29: FLP-CONV-ILHA | E29: 84396 | F29: LANCHONETE DANDARA MEDEIROS LTDA | G29: Sex | H29: 46171
B30: FLORIPA M | C30: 4026 | D30: FLP-CONV-ILHA | E30: 86129 | F30: MANOEL JERUSALEM DA SILVA SOARES | G30: Qui | H30: 46177 | I30: 1
B31: FLORIPA M | C31: 4026 | D31: FLP-CONV-ILHA | E31: 87204 | F31: COMERCIO DE LANCHES DEODORO LTDA | G31: Sex | H31: 46171
B32: FLORIPA M | C32: 4026 | D32: FLP-CONV-ILHA | E32: 88228 | F32: BADOFE LANCHES LTDA | G32: Sex | H32: 46171
B33: FLORIPA M | C33: 4026 | D33: FLP-CONV-ILHA | E33: 88559 | F33: FABIMAR LANCHES LTDA | G33: Qui | H33: 46177
B34: FLORIPA M | C34: 4026 | D34: FLP-CONV-ILHA | E34: 90701 | F34: CARIONI COMERCIO VAREJISTA DE COMB LTDA | G34: Qui | H34: 46170
B35: FLORIPA M | C35: 4026 | D35: FLP-CONV-ILHA | E35: 92163 | F35: MR. CHICO FOOD LTDA | G35: Seg | H35: 46174
B36: FLORIPA M | C36: 4026 | D36: FLP-CONV-ILHA | E36: 93212 | F36: RZR COMERCIO DE COMBUSTIVEIS LTDA | G36: Qua | H36: 46176 | I36: 1
B37: FLORIPA M | C37: 4026 | D37: FLP-CONV-ILHA | E37: 95971 | F37: POSTO GALO LTDA | G37: Ter | H37: 46175
B38: FLORIPA M | C38: 4026 | D38: FLP-CONV-ILHA | E38: 96586 | F38: RKZ COMERCIO DE COMBUSTIVEIS LTDA | G38: Qua | H38: 46176 | I38: 1
B39: FLORIPA M | C39: 4026 | D39: FLP-CONV-ILHA | E39: 98186 | F39: SAVI RESTAURANTE E LANCHONETE LTDA | G39: Sex | H39: 46171
B40: FLORIPA M | C40: 4026 | D40: FLP-CONV-ILHA | E40: 98749 | F40: LOJA DE CONVENIENCIAS FLORIPA LTDA | G40: Qua | H40: 46183
B41: FLORIPA M | C41: 4026 | D41: FLP-CONV-ILHA | E41: 99565 | F41: MARCLA COMERCIO DE ALIMENTOS LTDA | G41: Qui | H41: 46177
B42: FLORIPA M | C42: 4026 | D42: FLP-CONV-ILHA | E42: 99582 | F42: MDESTRI COMBUSTIVEIS E LUBRIFICANTES LTDA | G42: Ter | H42: 46182
...
